Workbook

Sheet Summary
A1: Does a senior backend loop in India still include DSA? (Oct 2024 to Oct 2026)
A2: All counts are live formulas over the Loops sheet. "Counted" = after same-author, same-company dedupe. Share = Yes / (Yes + No); Unclear rows are left out of the share.
A4: Slice | B4: Loops | C4: DSA yes | D4: DSA no | E4: Unclear | F4: DSA share | G4: Read this as
A5: All loops (headline) | B5: =COUNTIFS(Loops!$Z$2:$Z$108,"Y") -> 104 | C5: =COUNTIFS(Loops!$Z$2:$Z$108,"Y",Loops!$K$2:$K$108,"Yes") -> 90 | D5: =COUNTIFS(Loops!$Z$2:$Z$108,"Y",Loops!$K$2:$K$108,"No") -> 8 | E5: =COUNTIFS(Loops!$Z$2:$Z$108,"Y",Loops!$K$2:$K$108,"Unclear") -> 6 | F5: =IF(C5+D5=0,"",C5/(C5+D5)) -> 0.91836735 | G5: Everything kept
A6: Complete loops only | B6: =COUNTIFS(Loops!$Z$2:$Z$108,"Y",Loops!$X$2:$X$108,"N") -> 84 | C6: =COUNTIFS(Loops!$Z$2:$Z$108,"Y",Loops!$X$2:$X$108,"N",Loops!$K$2:$K$108,"Yes") -> 70 | D6: =COUNTIFS(Loops!$Z$2:$Z$108,"Y",Loops!$X$2:$X$108,"N",Loops!$K$2:$K$108,"No") -> 8 | E6: =COUNTIFS(Loops!$Z$2:$Z$108,"Y",Loops!$X$2:$X$108,"N",Loops!$K$2:$K$108,"Unclear") -> 6 | F6: =IF(C6+D6=0,"",C6/(C6+D6)) -> 0.8974359 | G6: Most honest number: partial loops were kept only if DSA showed up
A7: Partial loops | B7: =COUNTIFS(Loops!$Z$2:$Z$108,"Y",Loops!$X$2:$X$108,"Y") -> 20 | C7: =COUNTIFS(Loops!$Z$2:$Z$108,"Y",Loops!$X$2:$X$108,"Y",Loops!$K$2:$K$108,"Yes") -> 20 | D7: =COUNTIFS(Loops!$Z$2:$Z$108,"Y",Loops!$X$2:$X$108,"Y",Loops!$K$2:$K$108,"No") -> 0 | E7: =COUNTIFS(Loops!$Z$2:$Z$108,"Y",Loops!$X$2:$X$108,"Y",Loops!$K$2:$K$108,"Unclear") -> 0 | F7: =IF(C7+D7=0,"",C7/(C7+D7)) -> 1 | G7: 100% by rule, not a finding
A8: YoE <6 with senior title | B8: =COUNTIFS(Loops!$Z$2:$Z$108,"Y",Loops!$E$2:$E$108,"=<6") -> 16 | C8: =COUNTIFS(Loops!$Z$2:$Z$108,"Y",Loops!$E$2:$E$108,"=<6",Loops!$K$2:$K$108,"Yes") -> 16 | D8: =COUNTIFS(Loops!$Z$2:$Z$108,"Y",Loops!$E$2:$E$108,"=<6",Loops!$K$2:$K$108,"No") -> 0 | E8: =COUNTIFS(Loops!$Z$2:$Z$108,"Y",Loops!$E$2:$E$108,"=<6",Loops!$K$2:$K$108,"Unclear") -> 0 | F8: =IF(C8+D8=0,"",C8/(C8+D8)) -> 1
A9: YoE 6-7 | B9: =COUNTIFS(Loops!$Z$2:$Z$108,"Y",Loops!$E$2:$E$108,"6-7") -> 28 | C9: =COUNTIFS(Loops!$Z$2:$Z$108,"Y",Loops!$E$2:$E$108,"6-7",Loops!$K$2:$K$108,"Yes") -> 26 | D9: =COUNTIFS(Loops!$Z$2:$Z$108,"Y",Loops!$E$2:$E$108,"6-7",Loops!$K$2:$K$108,"No") -> 2 | E9: =COUNTIFS(Loops!$Z$2:$Z$108,"Y",Loops!$E$2:$E$108,"6-7",Loops!$K$2:$K$108,"Unclear") -> 0 | F9: =IF(C9+D9=0,"",C9/(C9+D9)) -> 0.92857143
A10: YoE 8-10 | B10: =COUNTIFS(Loops!$Z$2:$Z$108,"Y",Loops!$E$2:$E$108,"8-10") -> 11 | C10: =COUNTIFS(Loops!$Z$2:$Z$108,"Y",Loops!$E$2:$E$108,"8-10",Loops!$K$2:$K$108,"Yes") -> 9 | D10: =COUNTIFS(Loops!$Z$2:$Z$108,"Y",Loops!$E$2:$E$108,"8-10",Loops!$K$2:$K$108,"No") -> 2 | E10: =COUNTIFS(Loops!$Z$2:$Z$108,"Y",Loops!$E$2:$E$108,"8-10",Loops!$K$2:$K$108,"Unclear") -> 0 | F10: =IF(C10+D10=0,"",C10/(C10+D10)) -> 0.81818182 | G10: Closest band to you (12 yrs); small sample
A11: YoE 11+ | B11: =COUNTIFS(Loops!$Z$2:$Z$108,"Y",Loops!$E$2:$E$108,"11+") -> 2 | C11: =COUNTIFS(Loops!$Z$2:$Z$108,"Y",Loops!$E$2:$E$108,"11+",Loops!$K$2:$K$108,"Yes") -> 2 | D11: =COUNTIFS(Loops!$Z$2:$Z$108,"Y",Loops!$E$2:$E$108,"11+",Loops!$K$2:$K$108,"No") -> 0 | E11: =COUNTIFS(Loops!$Z$2:$Z$108,"Y",Loops!$E$2:$E$108,"11+",Loops!$K$2:$K$108,"Unclear") -> 0 | F11: =IF(C11+D11=0,"",C11/(C11+D11)) -> 1 | G11: Tiny sample
A12: YoE not stated | B12: =COUNTIFS(Loops!$Z$2:$Z$108,"Y",Loops!$E$2:$E$108,"not stated") -> 47 | C12: =COUNTIFS(Loops!$Z$2:$Z$108,"Y",Loops!$E$2:$E$108,"not stated",Loops!$K$2:$K$108,"Yes") -> 37 | D12: =COUNTIFS(Loops!$Z$2:$Z$108,"Y",Loops!$E$2:$E$108,"not stated",Loops!$K$2:$K$108,"No") -> 4 | E12: =COUNTIFS(Loops!$Z$2:$Z$108,"Y",Loops!$E$2:$E$108,"not stated",Loops!$K$2:$K$108,"Unclear") -> 6 | F12: =IF(C12+D12=0,"",C12/(C12+D12)) -> 0.90243902
A13: Year 2024-25 | B13: =COUNTIFS(Loops!$Z$2:$Z$108,"Y",Loops!$H$2:$H$108,"2024-25") -> 79 | C13: =COUNTIFS(Loops!$Z$2:$Z$108,"Y",Loops!$H$2:$H$108,"2024-25",Loops!$K$2:$K$108,"Yes") -> 68 | D13: =COUNTIFS(Loops!$Z$2:$Z$108,"Y",Loops!$H$2:$H$108,"2024-25",Loops!$K$2:$K$108,"No") -> 6 | E13: =COUNTIFS(Loops!$Z$2:$Z$108,"Y",Loops!$H$2:$H$108,"2024-25",Loops!$K$2:$K$108,"Unclear") -> 5 | F13: =IF(C13+D13=0,"",C13/(C13+D13)) -> 0.91891892
A14: Year 2026 | B14: =COUNTIFS(Loops!$Z$2:$Z$108,"Y",Loops!$H$2:$H$108,"2026") -> 25 | C14: =COUNTIFS(Loops!$Z$2:$Z$108,"Y",Loops!$H$2:$H$108,"2026",Loops!$K$2:$K$108,"Yes") -> 22 | D14: =COUNTIFS(Loops!$Z$2:$Z$108,"Y",Loops!$H$2:$H$108,"2026",Loops!$K$2:$K$108,"No") -> 2 | E14: =COUNTIFS(Loops!$Z$2:$Z$108,"Y",Loops!$H$2:$H$108,"2026",Loops!$K$2:$K$108,"Unclear") -> 1 | F14: =IF(C14+D14=0,"",C14/(C14+D14)) -> 0.91666667 | G14: AI era check
A15: Year 2026, complete loops | B15: =COUNTIFS(Loops!$Z$2:$Z$108,"Y",Loops!$H$2:$H$108,"2026",Loops!$X$2:$X$108,"N") -> 22 | C15: =COUNTIFS(Loops!$Z$2:$Z$108,"Y",Loops!$H$2:$H$108,"2026",Loops!$X$2:$X$108,"N",Loops!$K$2:$K$108,"Yes") -> 19 | D15: =COUNTIFS(Loops!$Z$2:$Z$108,"Y",Loops!$H$2:$H$108,"2026",Loops!$X$2:$X$108,"N",Loops!$K$2:$K$108,"No") -> 2 | E15: =COUNTIFS(Loops!$Z$2:$Z$108,"Y",Loops!$H$2:$H$108,"2026",Loops!$X$2:$X$108,"N",Loops!$K$2:$K$108,"Unclear") -> 1 | F15: =IF(C15+D15=0,"",C15/(C15+D15)) -> 0.9047619 | G15: AI era, unbiased slice
A16: Source: LeetCode | B16: =COUNTIFS(Loops!$Z$2:$Z$108,"Y",Loops!$I$2:$I$108,"LeetCode") -> 72 | C16: =COUNTIFS(Loops!$Z$2:$Z$108,"Y",Loops!$I$2:$I$108,"LeetCode",Loops!$K$2:$K$108,"Yes") -> 65 | D16: =COUNTIFS(Loops!$Z$2:$Z$108,"Y",Loops!$I$2:$I$108,"LeetCode",Loops!$K$2:$K$108,"No") -> 7 | E16: =COUNTIFS(Loops!$Z$2:$Z$108,"Y",Loops!$I$2:$I$108,"LeetCode",Loops!$K$2:$K$108,"Unclear") -> 0 | F16: =IF(C16+D16=0,"",C16/(C16+D16)) -> 0.90277778 | G16: Self-selected DSA crowd?
A17: Source: Taro + Glassdoor | B17: =COUNTIFS(Loops!$Z$2:$Z$108,"Y",Loops!$I$2:$I$108,"<>LeetCode") -> 32 | C17: =COUNTIFS(Loops!$Z$2:$Z$108,"Y",Loops!$I$2:$I$108,"<>LeetCode",Loops!$K$2:$K$108,"Yes") -> 25 | D17: =COUNTIFS(Loops!$Z$2:$Z$108,"Y",Loops!$I$2:$I$108,"<>LeetCode",Loops!$K$2:$K$108,"No") -> 1 | E17: =COUNTIFS(Loops!$Z$2:$Z$108,"Y",Loops!$I$2:$I$108,"<>LeetCode",Loops!$K$2:$K$108,"Unclear") -> 6 | F17: =IF(C17+D17=0,"",C17/(C17+D17)) -> 0.96153846 | G17: Different crowd, bias check
A18: YoE 8+ (8-10 plus 11+) | B18: =B10+B11 -> 13 | C18: =C10+C11 -> 11 | D18: =D10+D11 -> 2 | E18: =E10+E11 -> 0 | F18: =IF(C18+D18=0,"",C18/(C18+D18)) -> 0.84615385 | G18: Your band
A20: Where the interview time goes (complete loops with a clear DSA answer)
A21: Round type | B21: Rounds | C21: Share of all rounds | D21: Loops with it | E21: Share of loops
A22: DSA (incl. OA) | B22: =SUMIFS(Loops!$L$2:$L$108,Loops!$Z$2:$Z$108,"Y",Loops!$X$2:$X$108,"N",Loops!$K$2:$K$108,"<>Unclear") -> 122 | C22: =B22/B32 -> 0.31524548 | D22: =COUNTIFS(Loops!$Z$2:$Z$108,"Y",Loops!$X$2:$X$108,"N",Loops!$K$2:$K$108,"<>Unclear",Loops!$L$2:$L$108,">0") -> 70 | E22: =D22/COUNTIFS(Loops!$Z$2:$Z$108,"Y",Loops!$X$2:$X$108,"N",Loops!$K$2:$K$108,"<>Unclear") -> 0.8974359
A23: HLD / system design | B23: =SUMIFS(Loops!$P$2:$P$108,Loops!$Z$2:$Z$108,"Y",Loops!$X$2:$X$108,"N",Loops!$K$2:$K$108,"<>Unclear") -> 72 | C23: =B23/B32 -> 0.18604651 | D23: =COUNTIFS(Loops!$Z$2:$Z$108,"Y",Loops!$X$2:$X$108,"N",Loops!$K$2:$K$108,"<>Unclear",Loops!$P$2:$P$108,">0") -> 63 | E23: =D23/COUNTIFS(Loops!$Z$2:$Z$108,"Y",Loops!$X$2:$X$108,"N",Loops!$K$2:$K$108,"<>Unclear") -> 0.80769231
A24: HM / behavioral | B24: =SUMIFS(Loops!$V$2:$V$108,Loops!$Z$2:$Z$108,"Y",Loops!$X$2:$X$108,"N",Loops!$K$2:$K$108,"<>Unclear") -> 59 | C24: =B24/B32 -> 0.15245478 | D24: =COUNTIFS(Loops!$Z$2:$Z$108,"Y",Loops!$X$2:$X$108,"N",Loops!$K$2:$K$108,"<>Unclear",Loops!$V$2:$V$108,">0") -> 51 | E24: =D24/COUNTIFS(Loops!$Z$2:$Z$108,"Y",Loops!$X$2:$X$108,"N",Loops!$K$2:$K$108,"<>Unclear") -> 0.65384615
A25: Project deep-dive | B25: =SUMIFS(Loops!$S$2:$S$108,Loops!$Z$2:$Z$108,"Y",Loops!$X$2:$X$108,"N",Loops!$K$2:$K$108,"<>Unclear") -> 44 | C25: =B25/B32 -> 0.11369509 | D25: =COUNTIFS(Loops!$Z$2:$Z$108,"Y",Loops!$X$2:$X$108,"N",Loops!$K$2:$K$108,"<>Unclear",Loops!$S$2:$S$108,">0") -> 43 | E25: =D25/COUNTIFS(Loops!$Z$2:$Z$108,"Y",Loops!$X$2:$X$108,"N",Loops!$K$2:$K$108,"<>Unclear") -> 0.55128205
A26: LLD | B26: =SUMIFS(Loops!$O$2:$O$108,Loops!$Z$2:$Z$108,"Y",Loops!$X$2:$X$108,"N",Loops!$K$2:$K$108,"<>Unclear") -> 33 | C26: =B26/B32 -> 0.085271318 | D26: =COUNTIFS(Loops!$Z$2:$Z$108,"Y",Loops!$X$2:$X$108,"N",Loops!$K$2:$K$108,"<>Unclear",Loops!$O$2:$O$108,">0") -> 32 | E26: =D26/COUNTIFS(Loops!$Z$2:$Z$108,"Y",Loops!$X$2:$X$108,"N",Loops!$K$2:$K$108,"<>Unclear") -> 0.41025641
A27: Lang / CS fundamentals | B27: =SUMIFS(Loops!$U$2:$U$108,Loops!$Z$2:$Z$108,"Y",Loops!$X$2:$X$108,"N",Loops!$K$2:$K$108,"<>Unclear") -> 25 | C27: =B27/B32 -> 0.064599483 | D27: =COUNTIFS(Loops!$Z$2:$Z$108,"Y",Loops!$X$2:$X$108,"N",Loops!$K$2:$K$108,"<>Unclear",Loops!$U$2:$U$108,">0") -> 23 | E27: =D27/COUNTIFS(Loops!$Z$2:$Z$108,"Y",Loops!$X$2:$X$108,"N",Loops!$K$2:$K$108,"<>Unclear") -> 0.29487179
A28: Machine coding | B28: =SUMIFS(Loops!$N$2:$N$108,Loops!$Z$2:$Z$108,"Y",Loops!$X$2:$X$108,"N",Loops!$K$2:$K$108,"<>Unclear") -> 19 | C28: =B28/B32 -> 0.049095607 | D28: =COUNTIFS(Loops!$Z$2:$Z$108,"Y",Loops!$X$2:$X$108,"N",Loops!$K$2:$K$108,"<>Unclear",Loops!$N$2:$N$108,">0") -> 18 | E28: =D28/COUNTIFS(Loops!$Z$2:$Z$108,"Y",Loops!$X$2:$X$108,"N",Loops!$K$2:$K$108,"<>Unclear") -> 0.23076923
A29: AI concepts | B29: =SUMIFS(Loops!$R$2:$R$108,Loops!$Z$2:$Z$108,"Y",Loops!$X$2:$X$108,"N",Loops!$K$2:$K$108,"<>Unclear") -> 6 | C29: =B29/B32 -> 0.015503876 | D29: =COUNTIFS(Loops!$Z$2:$Z$108,"Y",Loops!$X$2:$X$108,"N",Loops!$K$2:$K$108,"<>Unclear",Loops!$R$2:$R$108,">0") -> 6 | E29: =D29/COUNTIFS(Loops!$Z$2:$Z$108,"Y",Loops!$X$2:$X$108,"N",Loops!$K$2:$K$108,"<>Unclear") -> 0.076923077
A30: Code review / debug | B30: =SUMIFS(Loops!$T$2:$T$108,Loops!$Z$2:$Z$108,"Y",Loops!$X$2:$X$108,"N",Loops!$K$2:$K$108,"<>Unclear") -> 5 | C30: =B30/B32 -> 0.012919897 | D30: =COUNTIFS(Loops!$Z$2:$Z$108,"Y",Loops!$X$2:$X$108,"N",Loops!$K$2:$K$108,"<>Unclear",Loops!$T$2:$T$108,">0") -> 5 | E30: =D30/COUNTIFS(Loops!$Z$2:$Z$108,"Y",Loops!$X$2:$X$108,"N",Loops!$K$2:$K$108,"<>Unclear") -> 0.064102564
A31: AI-assisted coding | B31: =SUMIFS(Loops!$Q$2:$Q$108,Loops!$Z$2:$Z$108,"Y",Loops!$X$2:$X$108,"N",Loops!$K$2:$K$108,"<>Unclear") -> 2 | C31: =B31/B32 -> 0.0051679587 | D31: =COUNTIFS(Loops!$Z$2:$Z$108,"Y",Loops!$X$2:$X$108,"N",Loops!$K$2:$K$108,"<>Unclear",Loops!$Q$2:$Q$108,">0") -> 2 | E31: =D31/COUNTIFS(Loops!$Z$2:$Z$108,"Y",Loops!$X$2:$X$108,"N",Loops!$K$2:$K$108,"<>Unclear") -> 0.025641026
A32: Total rounds | B32: =SUM(B22:B31) -> 387 | D32: =COUNTIFS(Loops!$Z$2:$Z$108,"Y",Loops!$X$2:$X$108,"N",Loops!$K$2:$K$108,"<>Unclear") -> 78 | E32: (loops in this block)
A34: Compare with the plan
A35: DSA hours in plan | B35: 117.5 | C35: Source: Phase1_Master_Plan_v3.3.md (hours table). Blue = typed-in input.
A36: Total plan hours | B36: 558
A37: DSA share of plan hours | B37: =B35/B36 -> 0.21057348
A38: DSA share of interview rounds | B38: =C22 -> 0.31524548

Sheet Loops
A1: # | B1: Company | C1: Title / level | D1: YoE | E1: YoE band | F1: Location | G1: Date | H1: Year group | I1: Source | J1: Link | K1: DSA asked? | L1: DSA rounds | M1: DSA difficulty | N1: Machine coding | O1: LLD | P1: HLD | Q1: AI-assisted coding | R1: AI concepts | S1: Project deep-dive | T1: Code review / debug | U1: Lang / CS fundamentals | V1: HM / behavioral | W1: Rounds counted | X1: Partial loop? | Y1: Same-author tag | Z1: Counted (dedup)? | AA1: Outcome | AB1: Note
A2: 1 | B2: Nutanix | C2: SMTS | E2: =IF(D2="","not stated",IF(D2<6,"<6",IF(D2<8,"6-7",IF(D2<11,"8-10","11+")))) -> not stated | F2: Bengaluru | G2: 2026-08 | H2: =IF(LEFT(G2,4)="2026","2026","2024-25") -> 2026 | I2: Glassdoor | J2: https://www.glassdoor.com/Interview/Nutanix-Interview-Questions-E429159.htm#SMTS-2026-08-04 | K2: =IF(ISNUMBER(L2),IF(L2>0,"Yes","No"),"Unclear") -> Unclear | L2: unclear | M2: not stated | N2: 0 | O2: 0 | P2: 1 | Q2: 0 | R2: 0 | S2: 0 | T2: 0 | U2: 0 | V2: 1 | W2: =IF(ISNUMBER(L2),L2+SUM(N2:V2),"") | X2: N | Z2: Y | AA2: accepted
A3: 2 | B3: Uber | C3: Senior SE | E3: =IF(D3="","not stated",IF(D3<6,"<6",IF(D3<8,"6-7",IF(D3<11,"8-10","11+")))) -> not stated | F3: Bengaluru | G3: 2026-06 | H3: =IF(LEFT(G3,4)="2026","2026","2024-25") -> 2026 | I3: Glassdoor | J3: https://www.glassdoor.co.in/Interview/Uber-Senior-Software-Engineer-Interview-Questions-EI_IE575263.0,4_KO5,29.htm#2026-06-02 | K3: =IF(ISNUMBER(L3),IF(L3>0,"Yes","No"),"Unclear") -> Yes | L3: 1 | M3: not stated | N3: 0 | O3: 0 | P3: 0 | Q3: 0 | R3: 0 | S3: 0 | T3: 0 | U3: 0 | V3: 0 | W3: =IF(ISNUMBER(L3),L3+SUM(N3:V3),"") -> 1 | X3: Y | Z3: Y | AA3: no offer after round 1 | AB3: round labelled coding; question algorithmic (rectangle-line intersections)
A4: 3 | B4: Salesforce | C4: SMTS | E4: =IF(D4="","not stated",IF(D4<6,"<6",IF(D4<8,"6-7",IF(D4<11,"8-10","11+")))) -> not stated | F4: Hyderabad | G4: 2026-06 | H4: =IF(LEFT(G4,4)="2026","2026","2024-25") -> 2026 | I4: Glassdoor | J4: https://www.glassdoor.com.au/Interview/Salesforce-Interview-E11159-RVW104386922.htm | K4: =IF(ISNUMBER(L4),IF(L4>0,"Yes","No"),"Unclear") -> Yes | L4: 2 | M4: medium | N4: 0 | O4: 0 | P4: 1 | Q4: 0 | R4: 0 | S4: 0 | T4: 0 | U4: 0 | V4: 1 | W4: =IF(ISNUMBER(L4),L4+SUM(N4:V4),"") -> 4 | X4: N | Z4: Y | AA4: offer | AB4: plus OA (easy/medium); DSA rounds: graphs, stacks, two pointers; HM deep dive on prod debugging
A5: 4 | B5: Razorpay | C5: Lead SE | E5: =IF(D5="","not stated",IF(D5<6,"<6",IF(D5<8,"6-7",IF(D5<11,"8-10","11+")))) -> not stated | F5: Bengaluru | G5: 2026-06 | H5: =IF(LEFT(G5,4)="2026","2026","2024-25") -> 2026 | I5: Glassdoor | J5: https://www.glassdoor.com/Interview/Razorpay-Interview-E1146550-RVW104471826.htm | K5: =IF(ISNUMBER(L5),IF(L5>0,"Yes","No"),"Unclear") -> Yes | L5: 1 | M5: medium | N5: 1 | O5: 0 | P5: 1 | Q5: 1 | R5: 0 | S5: 0 | T5: 0 | U5: 0 | V5: 1 | W5: =IF(ISNUMBER(L5),L5+SUM(N5:V5),"") -> 5 | X5: N | Z5: Y | AA5: offer | AB5: DSA only in the 45-min HackerRank OA (one medium, leaned easy); agentic coding round
A6: 5 | B6: Walmart | C6: Senior SE (IN4) | D6: 8.5 | E6: =IF(D6="","not stated",IF(D6<6,"<6",IF(D6<8,"6-7",IF(D6<11,"8-10","11+")))) -> 8-10 | F6: India (IN4 is a Walmart India level) | G6: 2026-04 | H6: =IF(LEFT(G6,4)="2026","2026","2024-25") -> 2026 | I6: LeetCode | J6: https://leetcode.com/discuss/post/8299285/walmart-ssein4-interview-experience-apri-te0v/ | K6: =IF(ISNUMBER(L6),IF(L6>0,"Yes","No"),"Unclear") -> Yes | L6: 1 | M6: medium | N6: 0 | O6: 1 | P6: 1 | Q6: 0 | R6: 0 | S6: 1 | T6: 0 | U6: 0 | V6: 1 | W6: =IF(ISNUMBER(L6),L6+SUM(N6:V6),"") -> 5 | X6: N | Z6: Y | AA6: offer, declined
A7: 6 | B7: Walmart | C7: SDE 3 | D7: 3.8 | E7: =IF(D7="","not stated",IF(D7<6,"<6",IF(D7<8,"6-7",IF(D7<11,"8-10","11+")))) -> <6 | F7: Bangalore | G7: 2026-03 | H7: =IF(LEFT(G7,4)="2026","2026","2024-25") -> 2026 | I7: LeetCode | J7: https://leetcode.com/discuss/post/7774527/walmart-sde-3-interview-experience-march-cvri/ | K7: =IF(ISNUMBER(L7),IF(L7>0,"Yes","No"),"Unclear") -> Yes | L7: 1 | M7: medium | N7: 0 | O7: 1 | P7: 0 | Q7: 0 | R7: 0 | S7: 1 | T7: 0 | U7: 1 | V7: 1 | W7: =IF(ISNUMBER(L7),L7+SUM(N7:V7),"") -> 5 | X7: N | Z7: Y | AA7: rejected
A8: 7 | B8: MongoDB | C8: SWE3 | D8: 6.75 | E8: =IF(D8="","not stated",IF(D8<6,"<6",IF(D8<8,"6-7",IF(D8<11,"8-10","11+")))) -> 6-7 | F8: Gurgaon | G8: 2026-03 | H8: =IF(LEFT(G8,4)="2026","2026","2024-25") -> 2026 | I8: LeetCode | J8: https://leetcode.com/discuss/post/7772003/mongodb-swe3-gurgaon-interview-selected-ivulh/ | K8: =IF(ISNUMBER(L8),IF(L8>0,"Yes","No"),"Unclear") -> Yes | L8: 1 | M8: medium | N8: 0 | O8: 0 | P8: 1 | Q8: 0 | R8: 0 | S8: 1 | T8: 0 | U8: 0 | V8: 1 | W8: =IF(ISNUMBER(L8),L8+SUM(N8:V8),"") -> 4 | X8: N | Z8: Y | AA8: offer | AB8: plus a real-world problem round (migration verifier alerts)
A9: 8 | B9: Salesforce | C9: SMTS (LMTS loop) | D9: 9 | E9: =IF(D9="","not stated",IF(D9<6,"<6",IF(D9<8,"6-7",IF(D9<11,"8-10","11+")))) -> 8-10 | F9: Hyderabad | G9: 2026-02 | H9: =IF(LEFT(G9,4)="2026","2026","2024-25") -> 2026 | I9: LeetCode | J9: https://leetcode.com/discuss/post/7840794/salesforce-smts-hyderabad-march-2026-off-0fi6/ | K9: =IF(ISNUMBER(L9),IF(L9>0,"Yes","No"),"Unclear") -> Yes | L9: 2 | M9: mixed | N9: 1 | O9: 1 | P9: 1 | Q9: 0 | R9: 0 | S9: 0 | T9: 0 | U9: 0 | V9: 1 | W9: =IF(ISNUMBER(L9),L9+SUM(N9:V9),"") -> 6 | X9: N | Z9: Y | AA9: offer (SMTS)
A10: 9 | B10: PhonePe | C10: SDE-III | D10: 6 | E10: =IF(D10="","not stated",IF(D10<6,"<6",IF(D10<8,"6-7",IF(D10<11,"8-10","11+")))) -> 6-7 | F10: India (PhonePe) | G10: 2026-02 | H10: =IF(LEFT(G10,4)="2026","2026","2024-25") -> 2026 | I10: LeetCode | J10: https://leetcode.com/discuss/post/7654415/ | K10: =IF(ISNUMBER(L10),IF(L10>0,"Yes","No"),"Unclear") -> Yes | L10: 1 | M10: hard | N10: 1 | O10: 0 | P10: 1 | Q10: 0 | R10: 0 | S10: 0 | T10: 0 | U10: 0 | V10: 0 | W10: =IF(ISNUMBER(L10),L10+SUM(N10:V10),"") -> 3 | X10: N | Z10: Y | AA10: rejected at HLD
A11: 10 | B11: Myntra | C11: Tech Lead | E11: =IF(D11="","not stated",IF(D11<6,"<6",IF(D11<8,"6-7",IF(D11<11,"8-10","11+")))) -> not stated | F11: India (multi-company post: Meesho, Cleartrip, CoinDCX) | G11: 2026-02 | H11: =IF(LEFT(G11,4)="2026","2026","2024-25") -> 2026 | I11: LeetCode | J11: https://leetcode.com/discuss/post/7698154/#myntra | K11: =IF(ISNUMBER(L11),IF(L11>0,"Yes","No"),"Unclear") -> Yes | L11: 1 | M11: not stated | N11: 0 | O11: 1 | P11: 1 | Q11: 0 | R11: 0 | S11: 0 | T11: 0 | U11: 0 | V11: 1 | W11: =IF(ISNUMBER(L11),L11+SUM(N11:V11),"") -> 4 | X11: N | Z11: Y | AA11: rejected | AB11: plus an OA; DSA questions were custom, based on team projects
A12: 11 | B12: JioHotstar | C12: Senior SDE (Backend) | E12: =IF(D12="","not stated",IF(D12<6,"<6",IF(D12<8,"6-7",IF(D12<11,"8-10","11+")))) -> not stated | F12: India (JioHotstar) | G12: 2026-02 | H12: =IF(LEFT(G12,4)="2026","2026","2024-25") -> 2026 | I12: LeetCode | J12: https://leetcode.com/discuss/post/7690154/ | K12: =IF(ISNUMBER(L12),IF(L12>0,"Yes","No"),"Unclear") -> No | L12: 0 | M12: n/a | N12: 0 | O12: 1 | P12: 2 | Q12: 0 | R12: 0 | S12: 1 | T12: 0 | U12: 0 | V12: 1 | W12: =IF(ISNUMBER(L12),L12+SUM(N12:V12),"") -> 5 | X12: N | Z12: Y | AA12: not stated | AB12: LLD round included coding a config service
A13: 12 | B13: PhonePe | C13: Software Engineer (5-7 yrs band) | D13: 6.75 | E13: =IF(D13="","not stated",IF(D13<6,"<6",IF(D13<8,"6-7",IF(D13<11,"8-10","11+")))) -> 6-7 | F13: Bangalore | G13: 2026-01 | H13: =IF(LEFT(G13,4)="2026","2026","2024-25") -> 2026 | I13: LeetCode | J13: https://leetcode.com/discuss/post/7770543/phonepe-software-engineer-5-7-years-bang-tppy/ | K13: =IF(ISNUMBER(L13),IF(L13>0,"Yes","No"),"Unclear") -> Yes | L13: 1 | M13: mixed | N13: 1 | O13: 0 | P13: 1 | Q13: 0 | R13: 0 | S13: 1 | T13: 0 | U13: 0 | V13: 1 | W13: =IF(ISNUMBER(L13),L13+SUM(N13:V13),"") -> 5 | X13: N | Z13: Y | AA13: selected
A14: 13 | B14: Paytm | C14: SSE | D14: 3.7 | E14: =IF(D14="","not stated",IF(D14<6,"<6",IF(D14<8,"6-7",IF(D14<11,"8-10","11+")))) -> <6 | F14: Noida | G14: 2026-01 | H14: =IF(LEFT(G14,4)="2026","2026","2024-25") -> 2026 | I14: LeetCode | J14: https://leetcode.com/discuss/post/7649720/paytm-interview-experience-sse-jan-2026-r44h2/ | K14: =IF(ISNUMBER(L14),IF(L14>0,"Yes","No"),"Unclear") -> Yes | L14: 3 | M14: medium | N14: 0 | O14: 1 | P14: 1 | Q14: 0 | R14: 0 | S14: 1 | T14: 0 | U14: 1 | V14: 0 | W14: =IF(ISNUMBER(L14),L14+SUM(N14:V14),"") -> 7 | X14: N | Z14: Y | AA14: selected
A15: 14 | B15: Cleartrip (Flipkart) | C15: SDE3 | E15: =IF(D15="","not stated",IF(D15<6,"<6",IF(D15<8,"6-7",IF(D15<11,"8-10","11+")))) -> not stated | F15: India | G15: 2026-01 | H15: =IF(LEFT(G15,4)="2026","2026","2024-25") -> 2026 | I15: LeetCode | J15: https://leetcode.com/discuss/post/7571535/ | K15: =IF(ISNUMBER(L15),IF(L15>0,"Yes","No"),"Unclear") -> Yes | L15: 2 | M15: medium | N15: 1 | O15: 0 | P15: 1 | Q15: 0 | R15: 0 | S15: 1 | T15: 0 | U15: 0 | V15: 1 | W15: =IF(ISNUMBER(L15),L15+SUM(N15:V15),"") -> 6 | X15: N | Z15: Y | AA15: not stated
A16: 15 | B16: Walmart | C16: not stated | D16: 7 | E16: =IF(D16="","not stated",IF(D16<6,"<6",IF(D16<8,"6-7",IF(D16<11,"8-10","11+")))) -> 6-7 | F16: India (same post) | G16: 2026 | H16: =IF(LEFT(G16,4)="2026","2026","2024-25") -> 2026 | I16: LeetCode | J16: https://leetcode.com/discuss/post/8477884/interview-summary-of-last-6-months-micro-y7a7/#walmart | K16: =IF(ISNUMBER(L16),IF(L16>0,"Yes","No"),"Unclear") -> Yes | L16: 1 | M16: medium | N16: 0 | O16: 1 | P16: 3 | Q16: 0 | R16: 0 | S16: 0 | T16: 0 | U16: 1 | V16: 0 | W16: =IF(ISNUMBER(L16),L16+SUM(N16:V16),"") -> 6 | X16: N | Y16: 8477884 | Z16: Y | AA16: not stated | AB16: two Walmart roles merged in one entry
A17: 16 | B17: Walmart | C17: Senior Engineer (hiring drive) | D17: 8 | E17: =IF(D17="","not stated",IF(D17<6,"<6",IF(D17<8,"6-7",IF(D17<11,"8-10","11+")))) -> 8-10 | F17: India (LPA) | G17: 2026 | H17: =IF(LEFT(G17,4)="2026","2026","2024-25") -> 2026 | I17: LeetCode | J17: https://leetcode.com/discuss/post/8428653/prep-and-interview-exp-for-seniorstaff-l-ki4x/#walmart-senior | K17: =IF(ISNUMBER(L17),IF(L17>0,"Yes","No"),"Unclear") -> Yes | L17: 2 | M17: mixed | N17: 0 | O17: 1 | P17: 1 | Q17: 0 | R17: 0 | S17: 0 | T17: 0 | U17: 1 | V17: 0 | W17: =IF(ISNUMBER(L17),L17+SUM(N17:V17),"") -> 5 | X17: N | Y17: 8428653 | Z17: Y | AA17: cleared, withdrew
A18: 17 | B18: Walmart | C18: Staff Engineer | D18: 8 | E18: =IF(D18="","not stated",IF(D18<6,"<6",IF(D18<8,"6-7",IF(D18<11,"8-10","11+")))) -> 8-10 | F18: India (LPA) | G18: 2026 | H18: =IF(LEFT(G18,4)="2026","2026","2024-25") -> 2026 | I18: LeetCode | J18: https://leetcode.com/discuss/post/8428653/prep-and-interview-exp-for-seniorstaff-l-ki4x/#walmart-staff | K18: =IF(ISNUMBER(L18),IF(L18>0,"Yes","No"),"Unclear") -> Yes | L18: 1 | M18: medium | N18: 0 | O18: 1 | P18: 1 | Q18: 0 | R18: 1 | S18: 0 | T18: 0 | U18: 0 | V18: 1 | W18: =IF(ISNUMBER(L18),L18+SUM(N18:V18),"") -> 5 | X18: N | Y18: 8428653 | Z18: N | AA18: offer | AB18: 30 min on AI tool usage and an AI knowledge-sharing project
A19: 18 | B19: ThoughtSpot | C19: not stated | D19: 8 | E19: =IF(D19="","not stated",IF(D19<6,"<6",IF(D19<8,"6-7",IF(D19<11,"8-10","11+")))) -> 8-10 | F19: India (same post) | G19: 2026 | H19: =IF(LEFT(G19,4)="2026","2026","2024-25") -> 2026 | I19: LeetCode | J19: https://leetcode.com/discuss/post/8428653/prep-and-interview-exp-for-seniorstaff-l-ki4x/#thoughtspot | K19: =IF(ISNUMBER(L19),IF(L19>0,"Yes","No"),"Unclear") -> Yes | L19: 1 | M19: hard | N19: 0 | O19: 0 | P19: 1 | Q19: 0 | R19: 0 | S19: 0 | T19: 0 | U19: 0 | V19: 0 | W19: =IF(ISNUMBER(L19),L19+SUM(N19:V19),"") -> 2 | X19: Y | Y19: 8428653 | Z19: Y | AA19: ghosted
A20: 19 | B20: Tekion | C20: not stated | D20: 7 | E20: =IF(D20="","not stated",IF(D20<6,"<6",IF(D20<8,"6-7",IF(D20<11,"8-10","11+")))) -> 6-7 | F20: India (same post) | G20: 2026 | H20: =IF(LEFT(G20,4)="2026","2026","2024-25") -> 2026 | I20: LeetCode | J20: https://leetcode.com/discuss/post/8477884/interview-summary-of-last-6-months-micro-y7a7/#tekion | K20: =IF(ISNUMBER(L20),IF(L20>0,"Yes","No"),"Unclear") -> Yes | L20: 1 | M20: medium | N20: 0 | O20: 1 | P20: 0 | Q20: 0 | R20: 0 | S20: 0 | T20: 0 | U20: 0 | V20: 0 | W20: =IF(ISNUMBER(L20),L20+SUM(N20:V20),"") -> 2 | X20: Y | Y20: 8477884 | Z20: Y | AA20: not stated
A21: 20 | B21: Swiggy | C21: SDE-3 | E21: =IF(D21="","not stated",IF(D21<6,"<6",IF(D21<8,"6-7",IF(D21<11,"8-10","11+")))) -> not stated | F21: India | G21: 2026 | H21: =IF(LEFT(G21,4)="2026","2026","2024-25") -> 2026 | I21: LeetCode | J21: https://leetcode.com/discuss/post/7823221/ | K21: =IF(ISNUMBER(L21),IF(L21>0,"Yes","No"),"Unclear") -> Yes | L21: 1 | M21: not stated | N21: 1 | O21: 1 | P21: 1 | Q21: 0 | R21: 0 | S21: 0 | T21: 0 | U21: 0 | V21: 0 | W21: =IF(ISNUMBER(L21),L21+SUM(N21:V21),"") -> 4 | X21: N | Z21: Y | AA21: not stated
A22: 21 | B22: Salesforce | C22: Senior SE | D22: 7 | E22: =IF(D22="","not stated",IF(D22<6,"<6",IF(D22<8,"6-7",IF(D22<11,"8-10","11+")))) -> 6-7 | F22: India (multi-company post: Flipkart, Big Billion, Naukri) | G22: 2026 | H22: =IF(LEFT(G22,4)="2026","2026","2024-25") -> 2026 | I22: LeetCode | J22: https://leetcode.com/discuss/post/8477884/interview-summary-of-last-6-months-micro-y7a7/#salesforce1 | K22: =IF(ISNUMBER(L22),IF(L22>0,"Yes","No"),"Unclear") -> Yes | L22: 3 | M22: mixed | N22: 0 | O22: 2 | P22: 3 | Q22: 0 | R22: 0 | S22: 1 | T22: 0 | U22: 1 | V22: 1 | W22: =IF(ISNUMBER(L22),L22+SUM(N22:V22),"") -> 11 | X22: N | Y22: 8477884 | Z22: Y | AA22: not stated
A23: 22 | B23: Salesforce | C23: not stated (second loop) | D23: 7 | E23: =IF(D23="","not stated",IF(D23<6,"<6",IF(D23<8,"6-7",IF(D23<11,"8-10","11+")))) -> 6-7 | F23: India (same post) | G23: 2026 | H23: =IF(LEFT(G23,4)="2026","2026","2024-25") -> 2026 | I23: LeetCode | J23: https://leetcode.com/discuss/post/8477884/interview-summary-of-last-6-months-micro-y7a7/#salesforce2 | K23: =IF(ISNUMBER(L23),IF(L23>0,"Yes","No"),"Unclear") -> Yes | L23: 1 | M23: medium | N23: 0 | O23: 1 | P23: 0 | Q23: 0 | R23: 0 | S23: 0 | T23: 0 | U23: 0 | V23: 0 | W23: =IF(ISNUMBER(L23),L23+SUM(N23:V23),"") -> 2 | X23: Y | Y23: 8477884 | Z23: N | AA23: rejected
A24: 23 | B24: Oracle Health | C24: SSE + AI role | D24: 7 | E24: =IF(D24="","not stated",IF(D24<6,"<6",IF(D24<8,"6-7",IF(D24<11,"8-10","11+")))) -> 6-7 | F24: India (same post) | G24: 2026 | H24: =IF(LEFT(G24,4)="2026","2026","2024-25") -> 2026 | I24: LeetCode | J24: https://leetcode.com/discuss/post/8477884/interview-summary-of-last-6-months-micro-y7a7/#oraclehealth | K24: =IF(ISNUMBER(L24),IF(L24>0,"Yes","No"),"Unclear") -> Yes | L24: 2 | M24: mixed | N24: 0 | O24: 0 | P24: 1 | Q24: 0 | R24: 1 | S24: 1 | T24: 0 | U24: 0 | V24: 2 | W24: =IF(ISNUMBER(L24),L24+SUM(N24:V24),"") -> 7 | X24: N | Y24: 8477884 | Z24: Y | AA24: rejected | AB24: HM asked about building MCP tools
A25: 24 | B25: Oracle Health | C25: IC4 | D25: 8 | E25: =IF(D25="","not stated",IF(D25<6,"<6",IF(D25<8,"6-7",IF(D25<11,"8-10","11+")))) -> 8-10 | F25: India (same post) | G25: 2026 | H25: =IF(LEFT(G25,4)="2026","2026","2024-25") -> 2026 | I25: LeetCode | J25: https://leetcode.com/discuss/post/8428653/prep-and-interview-exp-for-seniorstaff-l-ki4x/#oraclehealth | K25: =IF(ISNUMBER(L25),IF(L25>0,"Yes","No"),"Unclear") -> No | L25: 0 | M25: n/a | N25: 0 | O25: 0 | P25: 2 | Q25: 0 | R25: 0 | S25: 1 | T25: 0 | U25: 0 | V25: 2 | W25: =IF(ISNUMBER(L25),L25+SUM(N25:V25),"") -> 5 | X25: N | Y25: 8428653 | Z25: Y | AA25: IC4 offer, declined
A26: 25 | B26: Oracle Cloud | C26: not stated | D26: 7 | E26: =IF(D26="","not stated",IF(D26<6,"<6",IF(D26<8,"6-7",IF(D26<11,"8-10","11+")))) -> 6-7 | F26: India (same post) | G26: 2026 | H26: =IF(LEFT(G26,4)="2026","2026","2024-25") -> 2026 | I26: LeetCode | J26: https://leetcode.com/discuss/post/8477884/interview-summary-of-last-6-months-micro-y7a7/#oraclecloud | K26: =IF(ISNUMBER(L26),IF(L26>0,"Yes","No"),"Unclear") -> Yes | L26: 1 | M26: medium | N26: 0 | O26: 0 | P26: 1 | Q26: 0 | R26: 0 | S26: 1 | T26: 0 | U26: 1 | V26: 2 | W26: =IF(ISNUMBER(L26),L26+SUM(N26:V26),"") -> 6 | X26: N | Y26: 8477884 | Z26: Y | AA26: not stated
A27: 26 | B27: Oracle | C27: SMTS | E27: =IF(D27="","not stated",IF(D27<6,"<6",IF(D27<8,"6-7",IF(D27<11,"8-10","11+")))) -> not stated | F27: Chandigarh | G27: 2026 | H27: =IF(LEFT(G27,4)="2026","2026","2024-25") -> 2026 | I27: Glassdoor | J27: https://www.glassdoor.co.in/Interview/Oracle-Senior-Member-of-Technical-Staff-Interview-Questions-EI_IE1737.0,6_KO7,39.htm#2026-09-01 | K27: =IF(ISNUMBER(L27),IF(L27>0,"Yes","No"),"Unclear") -> Yes | L27: 2 | M27: not stated | N27: 0 | O27: 0 | P27: 0 | Q27: 0 | R27: 0 | S27: 0 | T27: 0 | U27: 1 | V27: 0 | W27: =IF(ISNUMBER(L27),L27+SUM(N27:V27),"") -> 3 | X27: N | Z27: Y | AA27: offer | AB27: DSA and core Java across multiple rounds; count of rounds not given
A28: 27 | B28: Flipkart | C28: not stated | D28: 7 | E28: =IF(D28="","not stated",IF(D28<6,"<6",IF(D28<8,"6-7",IF(D28<11,"8-10","11+")))) -> 6-7 | F28: India (same post) | G28: 2026 | H28: =IF(LEFT(G28,4)="2026","2026","2024-25") -> 2026 | I28: LeetCode | J28: https://leetcode.com/discuss/post/8477884/interview-summary-of-last-6-months-micro-y7a7/#flipkart | K28: =IF(ISNUMBER(L28),IF(L28>0,"Yes","No"),"Unclear") -> Yes | L28: 1 | M28: medium | N28: 1 | O28: 0 | P28: 1 | Q28: 0 | R28: 0 | S28: 0 | T28: 0 | U28: 0 | V28: 0 | W28: =IF(ISNUMBER(L28),L28+SUM(N28:V28),"") -> 3 | X28: N | Y28: 8477884 | Z28: Y | AA28: not stated
A29: 28 | B29: Rubrik | C29: not stated | D29: 8.5 | E29: =IF(D29="","not stated",IF(D29<6,"<6",IF(D29<8,"6-7",IF(D29<11,"8-10","11+")))) -> 8-10 | F29: India | G29: 2025-12 | H29: =IF(LEFT(G29,4)="2026","2026","2024-25") -> 2024-25 | I29: LeetCode | J29: https://leetcode.com/discuss/post/8319169/#rubrik | K29: =IF(ISNUMBER(L29),IF(L29>0,"Yes","No"),"Unclear") -> Yes | L29: 2 | M29: not stated | N29: 0 | O29: 0 | P29: 0 | Q29: 0 | R29: 0 | S29: 0 | T29: 1 | U29: 0 | V29: 0 | W29: =IF(ISNUMBER(L29),L29+SUM(N29:V29),"") -> 3 | X29: Y | Y29: 8319169 | Z29: Y | AA29: rejected after 2 rounds
A30: 29 | B30: Salesforce | C30: LMTS | D30: 8 | E30: =IF(D30="","not stated",IF(D30<6,"<6",IF(D30<8,"6-7",IF(D30<11,"8-10","11+")))) -> 8-10 | F30: India (LPA) | G30: 2025-11 | H30: =IF(LEFT(G30,4)="2026","2026","2024-25") -> 2024-25 | I30: LeetCode | J30: https://leetcode.com/discuss/post/7446936/ | K30: =IF(ISNUMBER(L30),IF(L30>0,"Yes","No"),"Unclear") -> Yes | L30: 2 | M30: medium | N30: 0 | O30: 1 | P30: 1 | Q30: 0 | R30: 0 | S30: 0 | T30: 0 | U30: 0 | V30: 1 | W30: =IF(ISNUMBER(L30),L30+SUM(N30:V30),"") -> 5 | X30: N | Z30: Y | AA30: offer, declined
A31: 30 | B31: Rakuten Symphony | C31: Senior SE | D31: 5.25 | E31: =IF(D31="","not stated",IF(D31<6,"<6",IF(D31<8,"6-7",IF(D31<11,"8-10","11+")))) -> <6 | F31: Bangalore | G31: 2025-11 | H31: =IF(LEFT(G31,4)="2026","2026","2024-25") -> 2024-25 | I31: LeetCode | J31: https://leetcode.com/discuss/post/7410581/ | K31: =IF(ISNUMBER(L31),IF(L31>0,"Yes","No"),"Unclear") -> Yes | L31: 1 | M31: easy | N31: 0 | O31: 0 | P31: 1 | Q31: 0 | R31: 1 | S31: 1 | T31: 0 | U31: 1 | V31: 1 | W31: =IF(ISNUMBER(L31),L31+SUM(N31:V31),"") -> 6 | X31: N | Z31: Y | AA31: offer | AB31: easy coding (Fibonacci, word count, non-repeating chars) inside fundamentals and HLD rounds; HM asked about LLMs and RAG
A32: 31 | B32: Omnissa (ex-VMware EUC) | C32: not stated | D32: 8.5 | E32: =IF(D32="","not stated",IF(D32<6,"<6",IF(D32<8,"6-7",IF(D32<11,"8-10","11+")))) -> 8-10 | F32: India | G32: 2025-11 | H32: =IF(LEFT(G32,4)="2026","2026","2024-25") -> 2024-25 | I32: LeetCode | J32: https://leetcode.com/discuss/post/8319169/#omnissa | K32: =IF(ISNUMBER(L32),IF(L32>0,"Yes","No"),"Unclear") -> Yes | L32: 1 | M32: medium | N32: 0 | O32: 0 | P32: 0 | Q32: 0 | R32: 0 | S32: 0 | T32: 0 | U32: 0 | V32: 0 | W32: =IF(ISNUMBER(L32),L32+SUM(N32:V32),"") -> 1 | X32: Y | Y32: 8319169 | Z32: Y | AA32: rejected early
A33: 32 | B33: Autodesk | C33: Senior SE | D33: 8 | E33: =IF(D33="","not stated",IF(D33<6,"<6",IF(D33<8,"6-7",IF(D33<11,"8-10","11+")))) -> 8-10 | F33: Bengaluru | G33: 2025-11 | H33: =IF(LEFT(G33,4)="2026","2026","2024-25") -> 2024-25 | I33: LeetCode | J33: https://leetcode.com/discuss/post/7386726/ | K33: =IF(ISNUMBER(L33),IF(L33>0,"Yes","No"),"Unclear") -> Yes | L33: 1 | M33: mixed | N33: 0 | O33: 0 | P33: 1 | Q33: 0 | R33: 0 | S33: 1 | T33: 0 | U33: 0 | V33: 1 | W33: =IF(ISNUMBER(L33),L33+SUM(N33:V33),"") -> 4 | X33: N | Z33: Y | AA33: offer indicated
A34: 33 | B34: Zeta | C34: SDE 3 | E34: =IF(D34="","not stated",IF(D34<6,"<6",IF(D34<8,"6-7",IF(D34<11,"8-10","11+")))) -> not stated | F34: Bangalore | G34: 2025-10 | H34: =IF(LEFT(G34,4)="2026","2026","2024-25") -> 2024-25 | I34: LeetCode | J34: https://leetcode.com/discuss/post/7384474/zeta-sde-3-bangalore-oct-2025-declined-o-715m/ | K34: =IF(ISNUMBER(L34),IF(L34>0,"Yes","No"),"Unclear") -> Yes | L34: 1 | M34: mixed | N34: 2 | O34: 0 | P34: 0 | Q34: 0 | R34: 0 | S34: 1 | T34: 0 | U34: 0 | V34: 1 | W34: =IF(ISNUMBER(L34),L34+SUM(N34:V34),"") -> 5 | X34: N | Z34: Y | AA34: offer (early SDE3), declined
A35: 34 | B35: Sixt | C35: SDE III | D35: 6 | E35: =IF(D35="","not stated",IF(D35<6,"<6",IF(D35<8,"6-7",IF(D35<11,"8-10","11+")))) -> 6-7 | F35: India (same post: PhonePe, Expedia) | G35: 2025-10 | H35: =IF(LEFT(G35,4)="2026","2026","2024-25") -> 2024-25 | I35: LeetCode | J35: https://leetcode.com/discuss/post/7253272/#sixt | K35: =IF(ISNUMBER(L35),IF(L35>0,"Yes","No"),"Unclear") -> Yes | L35: 1 | M35: hard | N35: 0 | O35: 0 | P35: 0 | Q35: 0 | R35: 0 | S35: 0 | T35: 0 | U35: 0 | V35: 0 | W35: =IF(ISNUMBER(L35),L35+SUM(N35:V35),"") -> 1 | X35: Y | Y35: 7253272 | Z35: Y | AA35: rejected
A36: 35 | B36: PhonePe | C36: Senior SE | D36: 6 | E36: =IF(D36="","not stated",IF(D36<6,"<6",IF(D36<8,"6-7",IF(D36<11,"8-10","11+")))) -> 6-7 | F36: India (same post) | G36: 2025-10 | H36: =IF(LEFT(G36,4)="2026","2026","2024-25") -> 2024-25 | I36: LeetCode | J36: https://leetcode.com/discuss/post/7253272/#phonepe | K36: =IF(ISNUMBER(L36),IF(L36>0,"Yes","No"),"Unclear") -> Yes | L36: 1 | M36: medium | N36: 1 | O36: 1 | P36: 0 | Q36: 0 | R36: 0 | S36: 0 | T36: 0 | U36: 0 | V36: 0 | W36: =IF(ISNUMBER(L36),L36+SUM(N36:V36),"") -> 3 | X36: N | Y36: 7253272 | Z36: Y | AA36: rejected after round 3
A37: 36 | B37: Oracle | C37: Senior SE | E37: =IF(D37="","not stated",IF(D37<6,"<6",IF(D37<8,"6-7",IF(D37<11,"8-10","11+")))) -> not stated | F37: Bengaluru | G37: 2025-10 | H37: =IF(LEFT(G37,4)="2026","2026","2024-25") -> 2024-25 | I37: Taro | J37: https://www.jointaro.com/interviews/companies/oracle/experiences/senior-software-engineer-october-13-2025-no-offer-negative-206c52ba/ | K37: =IF(ISNUMBER(L37),IF(L37>0,"Yes","No"),"Unclear") -> Yes | L37: 2 | M37: medium | N37: 0 | O37: 0 | P37: 1 | Q37: 0 | R37: 0 | S37: 0 | T37: 0 | U37: 0 | V37: 1 | W37: =IF(ISNUMBER(L37),L37+SUM(N37:V37),"") -> 4 | X37: N | Z37: Y | AA37: no offer | AB37: two coding rounds of LC-medium questions; HLD booking site
A38: 37 | B38: Oracle | C38: Principal SE | E38: =IF(D38="","not stated",IF(D38<6,"<6",IF(D38<8,"6-7",IF(D38<11,"8-10","11+")))) -> not stated | F38: Bengaluru | G38: 2025-10 | H38: =IF(LEFT(G38,4)="2026","2026","2024-25") -> 2024-25 | I38: Taro | J38: https://www.jointaro.com/interviews/companies/oracle/experiences/principal-software-engineer-bengaluru-karnataka-october-27-2025-accepted-offer-positive-30c4e456/ | K38: =IF(ISNUMBER(L38),IF(L38>0,"Yes","No"),"Unclear") -> Unclear | L38: unclear | M38: not stated | N38: 0 | O38: 0 | P38: 1 | Q38: 0 | R38: 0 | S38: 1 | T38: 0 | U38: 0 | V38: 1 | W38: =IF(ISNUMBER(L38),L38+SUM(N38:V38),"") | X38: N | Z38: Y | AA38: offer | AB38: round 1 with a principal engineer: problem-solving approach and core concepts, coding not stated
A39: 38 | B39: Nike | C39: SDE 3 | E39: =IF(D39="","not stated",IF(D39<6,"<6",IF(D39<8,"6-7",IF(D39<11,"8-10","11+")))) -> not stated | F39: Bangalore | G39: 2025-10 | H39: =IF(LEFT(G39,4)="2026","2026","2024-25") -> 2024-25 | I39: LeetCode | J39: https://leetcode.com/discuss/post/7318007/nike-sde-3-interview-experience-by-anony-xd5y/ | K39: =IF(ISNUMBER(L39),IF(L39>0,"Yes","No"),"Unclear") -> Yes | L39: 1 | M39: easy | N39: 0 | O39: 0 | P39: 1 | Q39: 0 | R39: 0 | S39: 1 | T39: 0 | U39: 0 | V39: 1 | W39: =IF(ISNUMBER(L39),L39+SUM(N39:V39),"") -> 4 | X39: N | Z39: Y | AA39: offer
A40: 39 | B40: Meesho | C40: SDE-3 | E40: =IF(D40="","not stated",IF(D40<6,"<6",IF(D40<8,"6-7",IF(D40<11,"8-10","11+")))) -> not stated | F40: India (Meesho) | G40: 2025-10 | H40: =IF(LEFT(G40,4)="2026","2026","2024-25") -> 2024-25 | I40: LeetCode | J40: https://leetcode.com/discuss/post/7259276/ | K40: =IF(ISNUMBER(L40),IF(L40>0,"Yes","No"),"Unclear") -> Yes | L40: 1 | M40: not stated | N40: 0 | O40: 1 | P40: 0 | Q40: 0 | R40: 0 | S40: 1 | T40: 0 | U40: 0 | V40: 0 | W40: =IF(ISNUMBER(L40),L40+SUM(N40:V40),"") -> 3 | X40: Y | Z40: Y | AA40: no offer
...

Sheet Method
A1: How this was built
A3: Question | B3: Om (12 yrs, backend/platform, India) asked: at my level, in the last 2 years, how many real interview loops include DSA? Need 100+ rows, each with a link.
A4: Window | B4: Interview or post date Oct 2024 to Oct 2026.
A5: Kept | B5: India location or an India-only employer (city, LPA/INR, Indian company); senior title (Senior/SDE3/Lead/Staff/Principal/SMTS/LMTS/IC3+) or 6+ yrs; software engineering role (not QA, support, desktop C++); at least one round described.
A6: Partial loops | B6: Candidate stopped early. Kept only when DSA was seen, because a stopped loop cannot show that DSA was absent. So partial loops are 100% DSA by rule. Use the "Complete loops" line as the honest number.
A7: Dedupe | B7: One author posting several companies = separate loops (tagged in "Same-author tag"). Same author + same company twice = counted once. Glassdoor and Taro mirror each other; one known mirror was dropped.
A8: Excluded | B8: See the Excluded sheet: every rejected link with its reason (below level, outside India, no rounds, before Oct 2024, deleted, etc.). Microsoft was left out as in the earlier quick study.
A9: DSA asked? | B9: Yes = at least one round (online test or live) asked a LeetCode-style algorithm or data-structure problem. A practical build task (machine coding, LLD with code, REST API in a repo) is NOT counted as DSA. Unclear = a round said only "technical" with no content.
A10: Date | B10: Month from the post title or text when given; else the post date; for undated LeetCode posts, estimated from the post number (used only to check the window).
A11: Sources | B11: LeetCode Discuss (most rows), Taro (jointaro.com interview pages), Glassdoor single reviews. Each row links to its source.
A12: Spot-check | B12: 8 random rows re-read against the source on 2026-10-14 with a neutral prompt: DSA yes/no matched 8 of 8. Round counts matched; 2 dates are post-number estimates, 1 India signal is employer-based.
A13: Limits | B13: Self-reported posts. People who write on LeetCode may be more DSA-focused; the Taro + Glassdoor line is the check on that. Only 13 rows state 8+ yrs, so the 8+ share has a wide error range. YoE is missing in about half the rows.

Sheet Excluded
A1: # | B1: Link | C1: Reason
A2: 1 | B2: https://leetcode.com/discuss/post/8293408/ | C2: location not stated (Atlassian P50)
A3: 2 | B3: https://leetcode.com/discuss/interview-experience/6489221/ | C3: location not stated (Nutanix MTS-4)
A4: 3 | B4: https://leetcode.com/discuss/post/7725248/ | C4: location not stated (eBay SDE-3)
A5: 4 | B5: https://leetcode.com/discuss/post/8546012/ | C5: location not stated (HackerRank senior backend, AI-assisted coding round)
A6: 5 | B6: https://leetcode.com/discuss/post/8569781/ | C6: below level, MTS 3.3 yrs (Adobe)
A7: 6 | B7: https://leetcode.com/discuss/post/7947916/ | C7: below level (Rubrik 2.5 yrs)
A8: 7 | B8: https://leetcode.com/discuss/post/8524180/ | C8: below level SDE2 targets
A9: 8 | B9: https://leetcode.com/discuss/post/6774570/ | C9: location not stated (Cohesity MTS-3, 2 yrs)
A10: 9 | B10: https://leetcode.com/discuss/post/8509983/ | C10: below level (Uber SDE II)
A11: 10 | B11: https://leetcode.com/discuss/post/7614788/ | C11: below level (Databricks SDE-II)
A12: 11 | B12: https://leetcode.com/discuss/post/6954860/ | C12: below level (Target SE 2 yrs)
A13: 12 | B13: https://leetcode.com/discuss/post/8076680/ | C13: no rounds (Okta comp post)
... A135: 134 | B135: https://www.glassdoor.co.in/Interview/Walmart-Interview-E715-RVW96816608.htm | C135: same review as Taro Walmart SSE Apr 21 2025 row (Taro mirrors it)
