Workbook

Sheet Summary
A1: Claude JD harvest, run 1 (India), retrieved 2026-10-27
A2: Spec: claude/harvest/HARVEST-SPEC-2026-10.md v2.1. All counts below are live formulas over the JDs, Coding and Excluded sheets.
A3: z for 95% range | B3: 1.96 | G3: Input: z value for a 95% Wilson score interval.
A5: Item | B5: Count | C5: Of | D5: Share | E5: 95% low | F5: 95% high | G5: How counted
A6: Accepted India JDs | B6: =COUNTA(JDs!A2:A71) -> 70 | G6: Rows in JDs (withdrawn ChatGPT-company rows removed).
A7: Excluded postings read | B7: =COUNTA(Excluded!A2:A227) -> 226 | G7: Rows in Excluded, incl. 3 withdrawn and unread pages.
A8: Lane a: Python-led backend infrastructure | B8: =COUNTIF(JDs!V2:V71,"a") -> 27 | C8: =$B$6 -> 70 | D8: =IF(C8=0,0,B8/C8) -> 0.38571429 | E8: =IF(C8=0,0,(D8+$B$3^2/(2*C8)-$B$3*SQRT(D8*(1-D8)/C8+$B$3^2/(4*C8^2)))/(1+$B$3^2/C8)) -> 0.28047518 | F8: =IF(C8=0,0,(D8+$B$3^2/(2*C8)+$B$3*SQRT(D8*(1-D8)/C8+$B$3^2/(4*C8^2)))/(1+$B$3^2/C8)) -> 0.50284479 | G8: lane column
A9: Lane b: Go and Kubernetes platform | B9: =COUNTIF(JDs!V2:V71,"b") -> 30 | C9: =$B$6 -> 70 | D9: =IF(C9=0,0,B9/C9) -> 0.42857143 | E9: =IF(C9=0,0,(D9+$B$3^2/(2*C9)-$B$3*SQRT(D9*(1-D9)/C9+$B$3^2/(4*C9^2)))/(1+$B$3^2/C9)) -> 0.31935125 | F9: =IF(C9=0,0,(D9+$B$3^2/(2*C9)+$B$3*SQRT(D9*(1-D9)/C9+$B$3^2/(4*C9^2)))/(1+$B$3^2/C9)) -> 0.54522373 | G9: lane column
A10: Lane c: controllers and operators | B10: =COUNTIF(JDs!V2:V71,"c") -> 7 | C10: =$B$6 -> 70 | D10: =IF(C10=0,0,B10/C10) -> 0.1 | E10: =IF(C10=0,0,(D10+$B$3^2/(2*C10)-$B$3*SQRT(D10*(1-D10)/C10+$B$3^2/(4*C10^2)))/(1+$B$3^2/C10)) -> 0.049288675 | F10: =IF(C10=0,0,(D10+$B$3^2/(2*C10)+$B$3*SQRT(D10*(1-D10)/C10+$B$3^2/(4*C10^2)))/(1+$B$3^2/C10)) -> 0.19233122 | G10: lane column
A11: Lane d: data-infrastructure platforms | B11: =COUNTIF(JDs!V2:V71,"d") -> 6 | C11: =$B$6 -> 70 | D11: =IF(C11=0,0,B11/C11) -> 0.085714286 | E11: =IF(C11=0,0,(D11+$B$3^2/(2*C11)-$B$3*SQRT(D11*(1-D11)/C11+$B$3^2/(4*C11^2)))/(1+$B$3^2/C11)) -> 0.039876127 | F11: =IF(C11=0,0,(D11+$B$3^2/(2*C11)+$B$3*SQRT(D11*(1-D11)/C11+$B$3^2/(4*C11^2)))/(1+$B$3^2/C11)) -> 0.17465877 | G11: lane column
A12: Go required (no alternative) | B12: =COUNTIF(Coding!E2:E71,"required") -> 19 | C12: =$B$6 -> 70 | D12: =IF(C12=0,0,B12/C12) -> 0.27142857 | E12: =IF(C12=0,0,(D12+$B$3^2/(2*C12)-$B$3*SQRT(D12*(1-D12)/C12+$B$3^2/(4*C12^2)))/(1+$B$3^2/C12)) -> 0.18119461 | F12: =IF(C12=0,0,(D12+$B$3^2/(2*C12)+$B$3*SQRT(D12*(1-D12)/C12+$B$3^2/(4*C12^2)))/(1+$B$3^2/C12)) -> 0.38544533 | G12: hand-coded from langs fields
A13: Go required or one allowed choice | B13: =COUNTIF(Coding!E2:E71,"required")+COUNTIF(Coding!E2:E71,"allowed") -> 51 | C13: =$B$6 -> 70 | D13: =IF(C13=0,0,B13/C13) -> 0.72857143 | E13: =IF(C13=0,0,(D13+$B$3^2/(2*C13)-$B$3*SQRT(D13*(1-D13)/C13+$B$3^2/(4*C13^2)))/(1+$B$3^2/C13)) -> 0.61455467 | F13: =IF(C13=0,0,(D13+$B$3^2/(2*C13)+$B$3*SQRT(D13*(1-D13)/C13+$B$3^2/(4*C13^2)))/(1+$B$3^2/C13)) -> 0.81880539 | G13: Go satisfies the language requirement
A14: Go named at all (incl. preferred) | B14: =COUNTIF(Coding!E2:E71,"<>none") -> 56 | C14: =$B$6 -> 70 | D14: =IF(C14=0,0,B14/C14) -> 0.8 | E14: =IF(C14=0,0,(D14+$B$3^2/(2*C14)-$B$3*SQRT(D14*(1-D14)/C14+$B$3^2/(4*C14^2)))/(1+$B$3^2/C14)) -> 0.69183135 | F14: =IF(C14=0,0,(D14+$B$3^2/(2*C14)+$B$3*SQRT(D14*(1-D14)/C14+$B$3^2/(4*C14^2)))/(1+$B$3^2/C14)) -> 0.87695372
A15: Python required (no alternative) | B15: =COUNTIF(Coding!F2:F71,"required") -> 5 | C15: =$B$6 -> 70 | D15: =IF(C15=0,0,B15/C15) -> 0.071428571 | E15: =IF(C15=0,0,(D15+$B$3^2/(2*C15)-$B$3*SQRT(D15*(1-D15)/C15+$B$3^2/(4*C15^2)))/(1+$B$3^2/C15)) -> 0.030893762 | F15: =IF(C15=0,0,(D15+$B$3^2/(2*C15)+$B$3*SQRT(D15*(1-D15)/C15+$B$3^2/(4*C15^2)))/(1+$B$3^2/C15)) -> 0.15655613 | G15: hand-coded from langs fields
A16: Python required or one allowed choice | B16: =COUNTIF(Coding!F2:F71,"required")+COUNTIF(Coding!F2:F71,"allowed") -> 34 | C16: =$B$6 -> 70 | D16: =IF(C16=0,0,B16/C16) -> 0.48571429 | E16: =IF(C16=0,0,(D16+$B$3^2/(2*C16)-$B$3*SQRT(D16*(1-D16)/C16+$B$3^2/(4*C16^2)))/(1+$B$3^2/C16)) -> 0.37245682 | F16: =IF(C16=0,0,(D16+$B$3^2/(2*C16)+$B$3*SQRT(D16*(1-D16)/C16+$B$3^2/(4*C16^2)))/(1+$B$3^2/C16)) -> 0.60045817 | G16: Python satisfies the language requirement
A17: Python named at all (incl. preferred) | B17: =COUNTIF(Coding!F2:F71,"<>none") -> 44 | C17: =$B$6 -> 70 | D17: =IF(C17=0,0,B17/C17) -> 0.62857143 | E17: =IF(C17=0,0,(D17+$B$3^2/(2*C17)-$B$3*SQRT(D17*(1-D17)/C17+$B$3^2/(4*C17^2)))/(1+$B$3^2/C17)) -> 0.51146985 | F17: =IF(C17=0,0,(D17+$B$3^2/(2*C17)+$B$3*SQRT(D17*(1-D17)/C17+$B$3^2/(4*C17^2)))/(1+$B$3^2/C17)) -> 0.73229518
A18: Kubernetes required | B18: =COUNTIF(Coding!G2:G71,"required") -> 39 | C18: =$B$6 -> 70 | D18: =IF(C18=0,0,B18/C18) -> 0.55714286 | E18: =IF(C18=0,0,(D18+$B$3^2/(2*C18)-$B$3*SQRT(D18*(1-D18)/C18+$B$3^2/(4*C18^2)))/(1+$B$3^2/C18)) -> 0.44083343 | F18: =IF(C18=0,0,(D18+$B$3^2/(2*C18)+$B$3*SQRT(D18*(1-D18)/C18+$B$3^2/(4*C18^2)))/(1+$B$3^2/C18)) -> 0.66750658 | G18: named in skills_required
A19: Kubernetes required or preferred | B19: =COUNTIF(Coding!G2:G71,"required")+COUNTIF(Coding!G2:G71,"preferred") -> 52 | C19: =$B$6 -> 70 | D19: =IF(C19=0,0,B19/C19) -> 0.74285714 | E19: =IF(C19=0,0,(D19+$B$3^2/(2*C19)-$B$3*SQRT(D19*(1-D19)/C19+$B$3^2/(4*C19^2)))/(1+$B$3^2/C19)) -> 0.62973648 | F19: =IF(C19=0,0,(D19+$B$3^2/(2*C19)+$B$3*SQRT(D19*(1-D19)/C19+$B$3^2/(4*C19^2)))/(1+$B$3^2/C19)) -> 0.83070858
A20: Kubernetes controllers or operators required | B20: =COUNTIF(JDs!AM2:AM71,"required") -> 5 | C20: =$B$6 -> 70 | D20: =IF(C20=0,0,B20/C20) -> 0.071428571 | E20: =IF(C20=0,0,(D20+$B$3^2/(2*C20)-$B$3*SQRT(D20*(1-D20)/C20+$B$3^2/(4*C20^2)))/(1+$B$3^2/C20)) -> 0.030893762 | F20: =IF(C20=0,0,(D20+$B$3^2/(2*C20)+$B$3*SQRT(D20*(1-D20)/C20+$B$3^2/(4*C20^2)))/(1+$B$3^2/C20)) -> 0.15655613 | G20: k8s_controllers column
A21: Kubernetes controllers required or preferred | B21: =COUNTIF(JDs!AM2:AM71,"required")+COUNTIF(JDs!AM2:AM71,"preferred") -> 9 | C21: =$B$6 -> 70 | D21: =IF(C21=0,0,B21/C21) -> 0.12857143 | E21: =IF(C21=0,0,(D21+$B$3^2/(2*C21)-$B$3*SQRT(D21*(1-D21)/C21+$B$3^2/(4*C21^2)))/(1+$B$3^2/C21)) -> 0.06914022 | F21: =IF(C21=0,0,(D21+$B$3^2/(2*C21)+$B$3*SQRT(D21*(1-D21)/C21+$B$3^2/(4*C21^2)))/(1+$B$3^2/C21)) -> 0.22664969
A22: Helm required | B22: =COUNTIF(JDs!AJ2:AJ71,"required") -> 6 | C22: =$B$6 -> 70 | D22: =IF(C22=0,0,B22/C22) -> 0.085714286 | E22: =IF(C22=0,0,(D22+$B$3^2/(2*C22)-$B$3*SQRT(D22*(1-D22)/C22+$B$3^2/(4*C22^2)))/(1+$B$3^2/C22)) -> 0.039876127 | F22: =IF(C22=0,0,(D22+$B$3^2/(2*C22)+$B$3*SQRT(D22*(1-D22)/C22+$B$3^2/(4*C22^2)))/(1+$B$3^2/C22)) -> 0.17465877 | G22: helm column
A23: Helm required or preferred | B23: =COUNTIF(JDs!AJ2:AJ71,"required")+COUNTIF(JDs!AJ2:AJ71,"preferred") -> 8 | C23: =$B$6 -> 70 | D23: =IF(C23=0,0,B23/C23) -> 0.11428571 | E23: =IF(C23=0,0,(D23+$B$3^2/(2*C23)-$B$3*SQRT(D23*(1-D23)/C23+$B$3^2/(4*C23^2)))/(1+$B$3^2/C23)) -> 0.059060584 | F23: =IF(C23=0,0,(D23+$B$3^2/(2*C23)+$B$3*SQRT(D23*(1-D23)/C23+$B$3^2/(4*C23^2)))/(1+$B$3^2/C23)) -> 0.20964432 | G23: decides v3.9 F4 together with Om's bar
A24: Terraform required | B24: =COUNTIF(JDs!AL2:AL71,"required") -> 8 | C24: =$B$6 -> 70 | D24: =IF(C24=0,0,B24/C24) -> 0.11428571 | E24: =IF(C24=0,0,(D24+$B$3^2/(2*C24)-$B$3*SQRT(D24*(1-D24)/C24+$B$3^2/(4*C24^2)))/(1+$B$3^2/C24)) -> 0.059060584 | F24: =IF(C24=0,0,(D24+$B$3^2/(2*C24)+$B$3*SQRT(D24*(1-D24)/C24+$B$3^2/(4*C24^2)))/(1+$B$3^2/C24)) -> 0.20964432 | G24: terraform column
A25: Terraform required or preferred | B25: =COUNTIF(JDs!AL2:AL71,"required")+COUNTIF(JDs!AL2:AL71,"preferred") -> 18 | C25: =$B$6 -> 70 | D25: =IF(C25=0,0,B25/C25) -> 0.25714286 | E25: =IF(C25=0,0,(D25+$B$3^2/(2*C25)-$B$3*SQRT(D25*(1-D25)/C25+$B$3^2/(4*C25^2)))/(1+$B$3^2/C25)) -> 0.16929142 | F25: =IF(C25=0,0,(D25+$B$3^2/(2*C25)+$B$3*SQRT(D25*(1-D25)/C25+$B$3^2/(4*C25^2)))/(1+$B$3^2/C25)) -> 0.37026352
A26: Public cloud required | B26: =COUNTIF(Coding!H2:H71,"required") -> 26 | C26: =$B$6 -> 70 | D26: =IF(C26=0,0,B26/C26) -> 0.37142857 | E26: =IF(C26=0,0,(D26+$B$3^2/(2*C26)-$B$3*SQRT(D26*(1-D26)/C26+$B$3^2/(4*C26^2)))/(1+$B$3^2/C26)) -> 0.26770482 | F26: =IF(C26=0,0,(D26+$B$3^2/(2*C26)+$B$3*SQRT(D26*(1-D26)/C26+$B$3^2/(4*C26^2)))/(1+$B$3^2/C26)) -> 0.48853015 | G26: any provider named in skills_required
A27: Public cloud required or preferred | B27: =COUNTIF(Coding!H2:H71,"required")+COUNTIF(Coding!H2:H71,"preferred") -> 36 | C27: =$B$6 -> 70 | D27: =IF(C27=0,0,B27/C27) -> 0.51428571 | E27: =IF(C27=0,0,(D27+$B$3^2/(2*C27)-$B$3*SQRT(D27*(1-D27)/C27+$B$3^2/(4*C27^2)))/(1+$B$3^2/C27)) -> 0.39954183 | F27: =IF(C27=0,0,(D27+$B$3^2/(2*C27)+$B$3*SQRT(D27*(1-D27)/C27+$B$3^2/(4*C27^2)))/(1+$B$3^2/C27)) -> 0.62754318
A28: AWS named anywhere in the JD | B28: =COUNTIF(Coding!I2:I71,"yes") -> 39 | C28: =$B$6 -> 70 | D28: =IF(C28=0,0,B28/C28) -> 0.55714286 | E28: =IF(C28=0,0,(D28+$B$3^2/(2*C28)-$B$3*SQRT(D28*(1-D28)/C28+$B$3^2/(4*C28^2)))/(1+$B$3^2/C28)) -> 0.44083343 | F28: =IF(C28=0,0,(D28+$B$3^2/(2*C28)+$B$3*SQRT(D28*(1-D28)/C28+$B$3^2/(4*C28^2)))/(1+$B$3^2/C28)) -> 0.66750658 | G28: skills, cloud or duties
A29: Production-history screen stated | B29: =COUNTIF(Coding!J2:J71,"yes") -> 60 | C29: =$B$6 -> 70 | D29: =IF(C29=0,0,B29/C29) -> 0.85714286 | E29: =IF(C29=0,0,(D29+$B$3^2/(2*C29)-$B$3*SQRT(D29*(1-D29)/C29+$B$3^2/(4*C29^2)))/(1+$B$3^2/C29)) -> 0.75661365 | F29: =IF(C29=0,0,(D29+$B$3^2/(2*C29)+$B$3*SQRT(D29*(1-D29)/C29+$B$3^2/(4*C29^2)))/(1+$B$3^2/C29)) -> 0.92051144 | G29: prod_history_screen not none
A30: ai_infra none | B30: =COUNTIF(JDs!AG2:AG71,"none") -> 52 | C30: =$B$6 -> 70 | D30: =IF(C30=0,0,B30/C30) -> 0.74285714 | E30: =IF(C30=0,0,(D30+$B$3^2/(2*C30)-$B$3*SQRT(D30*(1-D30)/C30+$B$3^2/(4*C30^2)))/(1+$B$3^2/C30)) -> 0.62973648 | F30: =IF(C30=0,0,(D30+$B$3^2/(2*C30)+$B$3*SQRT(D30*(1-D30)/C30+$B$3^2/(4*C30^2)))/(1+$B$3^2/C30)) -> 0.83070858
A31: ai_infra app (LLM features, RAG, agents) | B31: =COUNTIF(JDs!AG2:AG71,"app") -> 14 | C31: =$B$6 -> 70 | D31: =IF(C31=0,0,B31/C31) -> 0.2 | E31: =IF(C31=0,0,(D31+$B$3^2/(2*C31)-$B$3*SQRT(D31*(1-D31)/C31+$B$3^2/(4*C31^2)))/(1+$B$3^2/C31)) -> 0.12304628 | F31: =IF(C31=0,0,(D31+$B$3^2/(2*C31)+$B$3*SQRT(D31*(1-D31)/C31+$B$3^2/(4*C31^2)))/(1+$B$3^2/C31)) -> 0.30816865
A32: ai_infra platform (GPU, serving, inference on Kubernetes) | B32: =COUNTIF(JDs!AG2:AG71,"platform") -> 4 | C32: =$B$6 -> 70 | D32: =IF(C32=0,0,B32/C32) -> 0.057142857 | E32: =IF(C32=0,0,(D32+$B$3^2/(2*C32)-$B$3*SQRT(D32*(1-D32)/C32+$B$3^2/(4*C32^2)))/(1+$B$3^2/C32)) -> 0.022443416 | F32: =IF(C32=0,0,(D32+$B$3^2/(2*C32)+$B$3*SQRT(D32*(1-D32)/C32+$B$3^2/(4*C32^2)))/(1+$B$3^2/C32)) -> 0.13792147
A33: ai_infra engine (CUDA, kernels) | B33: =COUNTIF(JDs!AG2:AG71,"engine") -> 0 | C33: =$B$6 -> 70 | D33: =IF(C33=0,0,B33/C33) -> 0 | E33: =IF(C33=0,0,(D33+$B$3^2/(2*C33)-$B$3*SQRT(D33*(1-D33)/C33+$B$3^2/(4*C33^2)))/(1+$B$3^2/C33)) -> 0 | F33: =IF(C33=0,0,(D33+$B$3^2/(2*C33)+$B$3*SQRT(D33*(1-D33)/C33+$B$3^2/(4*C33^2)))/(1+$B$3^2/C33)) -> 0.052024875
A34: AI requirement marked required | B34: =COUNTIF(JDs!AI2:AI71,"required") -> 14 | C34: =$B$6 -> 70 | D34: =IF(C34=0,0,B34/C34) -> 0.2 | E34: =IF(C34=0,0,(D34+$B$3^2/(2*C34)-$B$3*SQRT(D34*(1-D34)/C34+$B$3^2/(4*C34^2)))/(1+$B$3^2/C34)) -> 0.12304628 | F34: =IF(C34=0,0,(D34+$B$3^2/(2*C34)+$B$3*SQRT(D34*(1-D34)/C34+$B$3^2/(4*C34^2)))/(1+$B$3^2/C34)) -> 0.30816865 | G34: includes 'use AI tools in engineering' lines
A35: AI requirement marked preferred | B35: =COUNTIF(JDs!AI2:AI71,"preferred") -> 8 | C35: =$B$6 -> 70 | D35: =IF(C35=0,0,B35/C35) -> 0.11428571 | E35: =IF(C35=0,0,(D35+$B$3^2/(2*C35)-$B$3*SQRT(D35*(1-D35)/C35+$B$3^2/(4*C35^2)))/(1+$B$3^2/C35)) -> 0.059060584 | F35: =IF(C35=0,0,(D35+$B$3^2/(2*C35)+$B$3*SQRT(D35*(1-D35)/C35+$B$3^2/(4*C35^2)))/(1+$B$3^2/C35)) -> 0.20964432
A36: Product backend rather than infrastructure | B36: =COUNTIF(Coding!M2:M71,"yes") -> 12 | C36: =$B$6 -> 70 | D36: =IF(C36=0,0,B36/C36) -> 0.17142857 | E36: =IF(C36=0,0,(D36+$B$3^2/(2*C36)-$B$3*SQRT(D36*(1-D36)/C36+$B$3^2/(4*C36^2)))/(1+$B$3^2/C36)) -> 0.10087626 | F36: =IF(C36=0,0,(D36+$B$3^2/(2*C36)+$B$3*SQRT(D36*(1-D36)/C36+$B$3^2/(4*C36^2)))/(1+$B$3^2/C36)) -> 0.27616866 | G36: hand-tagged
A37: Build share 'half' (ops share large) | B37: =COUNTIF(Coding!N2:N71,"half") -> 14 | C37: =$B$6 -> 70 | D37: =IF(C37=0,0,B37/C37) -> 0.2 | E37: =IF(C37=0,0,(D37+$B$3^2/(2*C37)-$B$3*SQRT(D37*(1-D37)/C37+$B$3^2/(4*C37^2)))/(1+$B$3^2/C37)) -> 0.12304628 | F37: =IF(C37=0,0,(D37+$B$3^2/(2*C37)+$B$3*SQRT(D37*(1-D37)/C37+$B$3^2/(4*C37^2)))/(1+$B$3^2/C37)) -> 0.30816865
A38: Band risk: minimum years 4 or fewer | B38: =COUNTIF(Coding!L2:L71,"yes") -> 5 | C38: =$B$6 -> 70 | D38: =IF(C38=0,0,B38/C38) -> 0.071428571 | E38: =IF(C38=0,0,(D38+$B$3^2/(2*C38)-$B$3*SQRT(D38*(1-D38)/C38+$B$3^2/(4*C38^2)))/(1+$B$3^2/C38)) -> 0.030893762 | F38: =IF(C38=0,0,(D38+$B$3^2/(2*C38)+$B$3*SQRT(D38*(1-D38)/C38+$B$3^2/(4*C38^2)))/(1+$B$3^2/C38)) -> 0.15655613 | G38: may sit below the 42L fixed gate
A39: Stretch level (Senior Staff or Principal) | B39: =COUNTIF(Coding!P2:P71,"yes") -> 5 | C39: =$B$6 -> 70 | D39: =IF(C39=0,0,B39/C39) -> 0.071428571 | E39: =IF(C39=0,0,(D39+$B$3^2/(2*C39)-$B$3*SQRT(D39*(1-D39)/C39+$B$3^2/(4*C39^2)))/(1+$B$3^2/C39)) -> 0.030893762 | F39: =IF(C39=0,0,(D39+$B$3^2/(2*C39)+$B$3*SQRT(D39*(1-D39)/C39+$B$3^2/(4*C39^2)))/(1+$B$3^2/C39)) -> 0.15655613
A40: Wider-internet employer (company_no web) | B40: =COUNTIF(JDs!B2:B71,"web") -> 11 | C40: =$B$6 -> 70 | D40: =IF(C40=0,0,B40/C40) -> 0.15714286 | E40: =IF(C40=0,0,(D40+$B$3^2/(2*C40)-$B$3*SQRT(D40*(1-D40)/C40+$B$3^2/(4*C40^2)))/(1+$B$3^2/C40)) -> 0.090075283 | F40: =IF(C40=0,0,(D40+$B$3^2/(2*C40)+$B$3*SQRT(D40*(1-D40)/C40+$B$3^2/(4*C40^2)))/(1+$B$3^2/C40)) -> 0.25988463 | G40: not on Claude's 100 list
A41: Posted date known (exact or day-level) | B41: =COUNTIF(Coding!O2:O71,"date") -> 15 | C41: =$B$6 -> 70 | D41: =IF(C41=0,0,B41/C41) -> 0.21428571 | E41: =IF(C41=0,0,(D41+$B$3^2/(2*C41)-$B$3*SQRT(D41*(1-D41)/C41+$B$3^2/(4*C41^2)))/(1+$B$3^2/C41)) -> 0.13438586 | F41: =IF(C41=0,0,(D41+$B$3^2/(2*C41)+$B$3*SQRT(D41*(1-D41)/C41+$B$3^2/(4*C41^2)))/(1+$B$3^2/C41)) -> 0.32391407 | G41: posted column has a date
...

Sheet Companies
A1: no | B1: company | C1: group | D1: searched_on | E1: postings_read | F1: accepted | G1: result_note
A2: C001 | B2: Nutanix | C2: Infra, cloud, storage, network, security, AI infra | D2: 2026-10-27 | E2: 9 | F2: 2 | G2: 2 accepted
A3: C002 | B3: Broadcom (VMware) | C3: Infra, cloud, storage, network, security, AI infra | D3: 2026-10-27 | E3: 1 | F3: 0 | G3: no fitting posting read; exclusions: closed or removed 1
A4: C003 | B4: Cisco | C4: Infra, cloud, storage, network, security, AI infra | D4: 2026-10-27 | E4: 4 | F4: 2 | G4: 2 accepted
A5: C004 | B5: Red Hat (IBM group, flag) | C5: Infra, cloud, storage, network, security, AI infra | D5: 2026-10-27 | E5: 5 | F5: 1 | G5: 1 accepted
A6: C005 | B6: Oracle (OCI) | C6: Infra, cloud, storage, network, security, AI infra | D6: 2026-10-27 | E6: 7 | F6: 1 | G6: 1 accepted
A7: C006 | B7: NetApp | C7: Infra, cloud, storage, network, security, AI infra | D7: 2026-10-27 | E7: 2 | F7: 2 | G7: 2 accepted
A8: C007 | B8: Pure Storage | C8: Infra, cloud, storage, network, security, AI infra | D8: 2026-10-27 | E8: 7 | F8: 5 | G8: 5 accepted
A9: C008 | B9: Dell Technologies | C9: Infra, cloud, storage, network, security, AI infra | D9: 2026-10-27 | E9: 3 | F9: 0 | G9: no fitting posting read; exclusions: closed or removed 2, unread or unverifiable 1
A10: C009 | B10: Hewlett Packard Enterprise | C10: Infra, cloud, storage, network, security, AI infra | D10: 2026-10-27 | E10: 7 | F10: 1 | G10: 1 accepted
A11: C010 | B11: Arista Networks | C11: Infra, cloud, storage, network, security, AI infra | D11: 2026-10-27 | E11: 2 | F11: 0 | G11: no fitting posting read; exclusions: closed or removed 2
A12: C011 | B12: F5 | C12: Infra, cloud, storage, network, security, AI infra | D12: 2026-10-27 | E12: 3 | F12: 1 | G12: 1 accepted
A13: C012 | B13: Palo Alto Networks | C13: Infra, cloud, storage, network, security, AI infra | D13: 2026-10-27 | E13: 5 | F13: 1 | G13: 1 accepted
... A32: C031 | B32: Snowflake | C32: Databases and data infrastructure | D32: 2026-10-27 | E32: 3 | F32: 0 | G32: no fitting posting read; exclusions: not India 2, closed or removed 1
A33: C032 | B33: Teradata | C33: Databases and data infrastructure | E33: 0 | F33: 0 | G33: not reached in this run; check LinkedIn/Naukri (Om) and re-run in W6
A34: C033 | B34: Informatica | C34: Databases and data infrastructure | E34: 0 | F34: 0 | G34: not reached in this run; check LinkedIn/Naukri (Om) and re-run in W6
A35: C034 | B35: Cloudera | C35: Databases and data infrastructure | D35: 2026-10-27 | E35: 3 | F35: 0 | G35: no fitting posting read; exclusions: not India 2, closed or removed 1
A36: C035 | B36: ThoughtSpot | C36: Databases and data infrastructure | D36: 2026-10-27 | E36: 2 | F36: 0 | G36: no fitting posting read; exclusions: closed or removed 1, unread or unverifiable 1
A37: C036 | B37: Atlassian | C37: Software platforms, SaaS, developer tools | D37: 2026-10-27 | E37: 2 | F37: 1 | G37: 1 accepted
A38: C037 | B38: ServiceNow | C38: Software platforms, SaaS, developer tools | D38: 2026-10-27 | E38: 13 | F38: 4 | G38: 4 accepted
A39: C038 | B39: Salesforce | C39: Software platforms, SaaS, developer tools | D39: 2026-10-27 | E39: 2 | F39: 0 | G39: no fitting posting read; exclusions: years outside fit 1, unread or unverifiable 1
A40: C039 | B40: Adobe | C40: Software platforms, SaaS, developer tools | D40: 2026-10-27 | E40: 3 | F40: 0 | G40: no fitting posting read; exclusions: unread or unverifiable 2, role identity (not backend infrastructure) 1
A41: C040 | B41: Intuit | C41: Software platforms, SaaS, developer tools | D41: 2026-10-27 | E41: 5 | F41: 4 | G41: 4 accepted
A42: C041 | B42: SAP Labs India | C42: Software platforms, SaaS, developer tools | D42: 2026-10-27 | E42: 1 | F42: 0 | G42: no fitting posting read; exclusions: older than 3 months 1
A43: C042 | B43: Freshworks | C43: Software platforms, SaaS, developer tools | D43: 2026-10-27 | E43: 2 | F43: 0 | G43: no fitting posting read; exclusions: years outside fit 1, unread or unverifiable 1
A44: C043 | B44: Postman | C44: Software platforms, SaaS, developer tools | D44: 2026-10-27 | E44: 1 | F44: 1 | G44: 1 accepted
A45: C044 | B45: Harness | C45: Software platforms, SaaS, developer tools | D45: 2026-10-27 | E45: 2 | F45: 0 | G45: no fitting posting read; exclusions: junior 1, other language required 1
A46: C045 | B46: Sprinklr | C46: Software platforms, SaaS, developer tools | E46: 0 | F46: 0 | G46: not reached in this run; check LinkedIn/Naukri (Om) and re-run in W6
A47: C046 | B47: Chargebee | C47: Software platforms, SaaS, developer tools | E47: 0 | F47: 0 | G47: not reached in this run; check LinkedIn/Naukri (Om) and re-run in W6
A48: C047 | B48: Rippling | C48: Software platforms, SaaS, developer tools | D48: 2026-10-27 | E48: 1 | F48: 0 | G48: no fitting posting read; exclusions: closed or removed 1
A49: C048 | B49: Twilio | C49: Software platforms, SaaS, developer tools | D49: 2026-10-27 | E49: 4 | F49: 0 | G49: no fitting posting read; exclusions: not India 2, unread or unverifiable 1
A50: C049 | B50: Okta | C50: Software platforms, SaaS, developer tools | D50: 2026-10-27 | E50: 4 | F50: 3 | G50: 3 accepted
A51: C050 | B51: Workday | C51: Software platforms, SaaS, developer tools | D51: 2026-10-27 | E51: 4 | F51: 0 | G51: no fitting posting read; exclusions: not India 3, unread or unverifiable 1
A52: C051 | B52: Uber | C52: Software platforms, SaaS, developer tools | D52: 2026-10-27 | E52: 3 | F52: 2 | G52: 2 accepted
A53: C052 | B53: Stripe | C53: Software platforms, SaaS, developer tools | D53: 2026-10-27 | E53: 4 | F53: 1 | G53: 1 accepted
A54: C053 | B54: Coinbase | C54: Software platforms, SaaS, developer tools | D54: 2026-10-27 | E54: 3 | F54: 0 | G54: no fitting posting read; exclusions: not India 2, unread or unverifiable 1
A55: C054 | B55: PayPal | C55: Banks, payments and retail tech centres (GCCs) | D55: 2026-10-27 | E55: 2 | F55: 1 | G55: 1 accepted
A56: C055 | B56: Visa | C56: Banks, payments and retail tech centres (GCCs) | D56: 2026-10-27 | E56: 2 | F56: 1 | G56: 1 accepted
A57: C056 | B57: Mastercard | C57: Banks, payments and retail tech centres (GCCs) | D57: 2026-10-27 | E57: 5 | F57: 0 | G57: no fitting posting read; exclusions: SRE, DevOps or ops duties 2, other language required 2
A58: C057 | B58: American Express | C58: Banks, payments and retail tech centres (GCCs) | D58: 2026-10-27 | E58: 2 | F58: 1 | G58: 1 accepted
...

Sheet JDs
A1: id | B1: company_no | C1: region | D1: country | E1: city | F1: employer | G1: title | H1: req_id | I1: url | J1: source | K1: retrieved | L1: posted | M1: status | N1: work_summary | O1: build_share | P1: level | Q1: years_asked | R1: langs_required | S1: langs_alt_or_optional | T1: skills_required | U1: skills_preferred | V1: lane | W1: prod_history_screen | X1: om_evidence | Y1: work_model | Z1: pay_stated | AA1: english_team | AB1: local_language | AC1: language_years_screen | AD1: interview_format | AE1: where_held | AF1: india_candidates | AG1: ai_infra | AH1: ai_terms | AI1: ai_req | AJ1: helm | AK1: public_cloud | AL1: terraform | AM1: k8s_controllers | AN1: notes
A2: CL-001 | B2: C006 | C2: India | D2: India | E2: Bengaluru | F2: NetApp | G2: Senior Software Engineer (Golang and Kubernetes) | H2: 130878-en_US | I2: https://careers.netapp.com/job/bengaluru/senior-software-engineer-golang-and-kubernetes/27600/82076511936 | J2: career page | K2: 2026-10-27 | L2: unknown | M2: open | N2: Build Trident, NetApp open-source dynamic storage provisioner for Kubernetes, and drive its upstream adoption | O2: most | P2: Senior | Q2: 8-11 | R2: Go; Python | S2: none | T2: Go (product); Python (product); Kubernetes in depth (capability); AWS, GCP and Azure working knowledge (product); cloud-native storage (capability); test automation (capability); debugging and performance analysis (capability) | U2: none | V2: b | W2: none | X2: none | Y2: hybrid | Z2: unknown | AA2: n/a | AB2: n/a | AC2: n/a | AD2: n/a | AE2: n/a | AF2: n/a | AG2: none | AH2: none | AI2: none | AJ2: none | AK2: AWS, GCP and Azure required (working knowledge) | AL2: none | AM2: none | AN2: Responsibilities section empty on the page; lane b because the product is Kubernetes storage provisioning in Go; open-source upstream work
A3: CL-002 | B3: C006 | C3: India | D3: India | E3: Bengaluru | F3: NetApp | G3: Senior Software Engineer (Cloud-Native Services, Go, Kubernetes, AWS/Azure) | H3: 135670 | I3: https://jobs.netapp.com/job/Bangalore%2C-Karnataka-Senior-Software-Engineer-%28Cloud-Native-Services%2C-Go%2C-Kubernetes%2C-AWSAzure%29/1407518000/ | J3: career page | K3: 2026-10-27 | L3: unknown | M3: open | N3: Build and run cloud-scale distributed services for Azure NetApp Files, from development to production reliability | O3: most | P3: Senior | Q3: 8+ (3+ in storage or data management) | R3: Go | S3: Python expected; C/C++, C#, React, TypeScript desirable | T3: Go (product); REST APIs (capability); microservices (capability); Kubernetes and containers (product); CI/CD (capability); observability (capability); distributed systems (capability); storage or data protection (capability) | U3: C/C++ (product); C# (product); React (product); TypeScript (product) | V3: d | W3: large-scale production environments; 3+ years on storage or data platforms | X3: IBM Cloud Databases classic, managed databases on Kubernetes in production (per plan s2, Om to confirm) | Y3: unknown | Z3: unknown | AA3: n/a | AB3: n/a | AC3: n/a | AD3: n/a | AE3: n/a | AF3: n/a | AG3: none | AH3: AI-native engineering practices (general mention only) | AI3: none | AJ3: none | AK3: Azure, AWS or GCP required | AL3: none | AM3: none | AN3: lane d: storage data-platform software, building is the main duty
A4: CL-003 | B4: C007 | C4: India | D4: India | E4: Bengaluru | F4: Pure Storage (Everpure) | G4: Member of Technical Staff, Backend - Portworx Enterprise | H4: 8053512 (Greenhouse job ID) | I4: https://job-boards.greenhouse.io/purestorage/jobs/8053512 | J4: ATS | K4: 2026-10-27 | L4: unknown | M4: open | N4: Design and build cloud-native microservices for Portworx Kubernetes storage, owning them across distributed systems of thousands of nodes | O4: most | P4: MTS (not stated as Senior) | Q4: 4+ | R4: none named | S4: Go preferred | T4: microservices (capability); cloud-native platforms (capability); distributed systems at thousands of nodes (capability); debugging at scale in public or private cloud (capability); data structures, algorithms and design (capability) | U4: Go (product) | V4: b | W4: customer deployments and production-quality software (no years screen) | X4: IBM IKS upgrades across 200-300 clusters, production (per plan s2, Om to confirm) | Y4: onsite | Z4: unknown | AA4: n/a | AB4: n/a | AC4: n/a | AD4: n/a | AE4: n/a | AF4: n/a | AG4: none | AH4: AI tooling for debugging (general) | AI4: none | AJ4: none | AK4: public or private cloud debugging (no provider) | AL4: none | AM4: none | AN4: 4+ years asked and no level given: may sit below Om s Senior band; Pure Storage now brands as Everpure
A5: CL-004 | B5: C013 | C5: India | D5: India | E5: Bengaluru | F5: Zscaler | G5: Staff Software Development Engineer (Backend - Python/Go/Rust) | H5: 5184112007 (Greenhouse job ID) | I5: https://job-boards.greenhouse.io/zscaler/jobs/5184112007 | J5: board | K5: 2026-10-27 | L5: unknown | M5: open | N5: Design, scale and run backend services and APIs on Kubernetes and cloud, including incident response and root-cause analysis | O5: half | P5: Staff | Q5: 5+ owning production backend services | R5: one of Python, Go or Rust strong, a second at working level | S5: C/C++ familiarity optional | T5: production backend and distributed systems (capability); high-volume APIs on containers and Kubernetes (capability); cloud (capability); system design and reliability (capability); distributed root-cause analysis (capability); foundational AI/ML understanding (capability); AI-assisted development (capability) | U5: multi-cloud Kubernetes in production (capability); SSO, OAuth, OIDC (product); observability: metrics, logs, traces (capability) | V5: a | W5: 5+ years owning production backend services | X5: IBM IKS upgrade programme and Circuit Breaker in production; Python backend only in personal PRCP (per plan s2, Om to confirm) | Y5: hybrid | Z5: unknown | AA5: n/a | AB5: n/a | AC5: n/a | AD5: n/a | AE5: n/a | AF5: n/a | AG5: none | AH5: foundational AI/ML understanding; AI-assisted development | AI5: required (general literacy only) | AJ5: none | AK5: AWS or GCP preferred | AL5: none | AM5: none | AN5: read on the Dreamwork mirror (updated 6 days before retrieval); the mirror pay range is its own estimate, not stated by Zscaler, so left out; lane a: Python allowed, backend infrastructure; build vs operate is about equal
A6: CL-005 | B6: C020 | C6: India | D6: India | E6: Bengaluru | F6: Commvault | G6: Backend - Senior Engineer (Clumio) | H6: 5376612008 (Greenhouse job ID) | I6: https://job-boards.greenhouse.io/commvault/jobs/5376612008 | J6: ATS | K6: 2026-10-27 | L6: unknown | M6: open | N6: Design, build and run backend services for the control and management plane of a cloud-native data protection platform | O6: most | P6: Senior | Q6: 4+ | R6: one of Go, Python, Java or Rust | S6: Go preferred | T6: one modern language (capability); operating non-trivial production systems (capability); turning loose requirements into solutions (capability) | U6: Go (product); security (capability); SaaS (capability) | V6: a | W6: operates production systems, on-call | X6: IBM production on-call and Sev 1 handling (per plan s2, Om to confirm) | Y6: unknown | Z6: unknown | AA6: n/a | AB6: n/a | AC6: n/a | AD6: n/a | AE6: n/a | AF6: n/a | AG6: none | AH6: none | AI6: none | AJ6: none | AK6: none named (cloud-native) | AL6: none | AM6: none | AN6: JD says most time is writing and reviewing production code; language-flexible, no Kubernetes named; 4+ years may sit below Om s band
A7: CL-006 | B7: C025 | C7: India | D7: India | E7: Bengaluru | F7: Sarvam AI | G7: Platform Engineer - AI Infrastructure | H7: fcb15601-6440-41f7-aa79-b9992057a4b2 (Ashby ID) | I7: https://www.sarvam.ai/careers/jobs/fcb15601-6440-41f7-aa79-b9992057a4b2 | J7: career page | K7: 2026-10-27 | L7: unknown | M7: open | N7: Build the GPU and serving platform on Kubernetes: scheduling, routing, rollout, autoscaling for training and inference workloads | O7: most | P7: not stated (5+ years) | Q7: 5+ building infrastructure or platform software | R7: Go or Python | S7: none | T7: Go or Python software engineering (capability); Kubernetes controllers, scheduler and API machinery, has written operators (capability); MIG and GPU sharing (capability); gang scheduling (capability); topology and fabric-aware placement (capability); owning a capability end to end (capability) | U7: serving or training platforms (capability); GPU schedulers Kueue, Volcano, Slurm, Run:ai (product); MIG, MPS, time-slicing as self-service (capability); Kubernetes networking CNI, RDMA, SR-IOV (capability); on-premise GPU (capability); open-source contributions (capability) | V7: c | W7: track record of systems designed and shipped | X7: IBM IKS upgrade automation; no controller or GPU work yet (per plan s2, Om to confirm) | Y7: onsite | Z7: unknown | AA7: n/a | AB7: n/a | AC7: n/a | AD7: n/a | AE7: n/a | AF7: n/a | AG7: platform | AH7: GPU scheduling; MIG; gang scheduling; Kueue; Volcano; Slurm; Run:ai; model serving; inference | AI7: required | AJ7: none | AK7: none | AL7: none | AM7: required | AN7: read in full earlier on Oct 27 (19:00 review); inference serving itself is a bonus, GPU scheduling is required
A8: CL-007 | B8: C025 | C8: India | D8: India | E8: Bengaluru | F8: Sarvam AI | G8: Staff Engineer, Product Infrastructure | H8: 10f11bb2-fe15-4743-9b3f-81da6743ea6a | I8: https://www.sarvam.ai/careers/jobs/10f11bb2-fe15-4743-9b3f-81da6743ea6a | J8: career page | K8: 2026-10-27 | L8: unknown | M8: open | N8: Own the backend of a conversational AI platform for voice agents: data model, APIs, workflow orchestration, reliability and observability | O8: most | P8: Staff IC | Q8: 5-10 | R8: Python (FastAPI) or Go | S8: none | T8: Python and FastAPI or Go (product); full system ownership (capability); workflow orchestration at scale, ideally Temporal (product); multi-tenant low-latency distributed systems (capability); PostgreSQL (product); Redis (product) | U8: products on LLMs or AI/ML (capability); telephony, VoIP, SIP (capability); startup experience (capability) | V8: a | W8: operating systems in production under real load | X8: PRCP is FastAPI and Postgres but personal; IBM production ownership (per plan s2, Om to confirm) | Y8: onsite | Z8: unknown | AA8: n/a | AB8: n/a | AC8: n/a | AD8: n/a | AE8: n/a | AF8: n/a | AG8: app | AH8: LLMs; voice agents | AI8: preferred | AJ8: none | AK8: none | AL8: none | AM8: none | AN8: Python-led backend infrastructure for an AI product; LLM work only a nice-to-have
A9: CL-008 | B9: C024 | C9: India | D9: India | E9: Bengaluru | F9: DigitalOcean | G9: Senior Software Engineer I, Compute | H9: JR 2026-8174 (gh_jid 8193220) | I9: https://www.digitalocean.com/careers/position/apply/?gh_jid=8193220 | J9: board | K9: 2026-10-27 | L9: unknown | M9: open | N9: Lead technical execution on the Compute distributed control plane, building Go microservices and core infrastructure, with on-call | O9: most | P9: Senior | Q9: unknown | R9: Go | S9: none | T9: Go (product); microservices (capability); distributed control plane or low-latency infrastructure APIs (capability); containers, virtualization or cloud-native such as Kubernetes or Firecracker (capability); distributed systems and concurrency (capability); Linux network performance tuning (capability); leading projects and mentoring (capability); gRPC and REST (product) | U9: none | V9: b | W9: production incident troubleshooting and on-call (no years screen) | X9: IBM production incident handling (per plan s2, Om to confirm) | Y9: hybrid | Z9: unknown | AA9: n/a | AB9: n/a | AC9: n/a | AD9: n/a | AE9: n/a | AF9: n/a | AG9: none | AH9: none in role (company blurb mentions inference) | AI9: none | AJ9: none | AK9: none | AL9: none | AM9: none | AN9: read on the Dreamwork mirror (updated 4 days before retrieval); the page gives no required/preferred split
A10: CL-009 | B10: web | C10: India | D10: India | E10: Bengaluru | F10: Roku | G10: Senior Software Engineer - Kubernetes & Service Mesh | H10: 11374 | I10: https://www.weareroku.com/jobs/senior-software-engineer-platform-engineering-bengaluru-karnataka-india | J10: career page | K10: 2026-10-27 | L10: unknown | M10: open | N10: Build and run a multi-cloud Kubernetes and Istio service mesh platform, coding in Go and Python, with cost tooling and some SRE duties | O10: half | P10: Senior | Q10: 8+ | R10: Go or another systems language; Python or another scripting language | S10: none | T10: Kubernetes in depth: EKS, GKE, AKS (product); service mesh, Istio (product); infrastructure automation design (capability); CI/CD (capability); observability: Prometheus, Thanos, Loki, Grafana (product); agentic systems: agents, MCP servers (capability) | U10: AWS (product); GCP or Azure (product) | V10: b | W10: large-scale systems with significant traffic (no years screen beyond 8+) | X10: IBM IKS upgrade programme across 200-300 clusters (per plan s2, Om to confirm) | Y10: hybrid | Z10: unknown | AA10: n/a | AB10: n/a | AC10: n/a | AD10: n/a | AE10: n/a | AF10: n/a | AG10: none | AH10: agents; MCP servers; Claude Code; Cursor | AI10: required (agentic tooling, not AI infrastructure) | AJ10: none | AK10: AWS preferred; GCP or Azure a plus | AL10: preferred | AM10: none | AN10: company not on Claude s list (wider internet); platform role with real SRE share, build_share half; Terraform listed as a tool used
A11: CL-010 | B11: C027 | C11: India | D11: India | E11: Bengaluru | F11: MongoDB | G11: Senior Software Engineer (Bengaluru Products & Technology) | H11: 3273539412 (gh_jid 8178900) | I11: https://www.mongodb.com/careers/job/?gh_jid=8178900 | J11: board | K11: 2026-10-27 | L11: unknown | M11: open | N11: Build a new platform that makes it easier for customers to build and run AI applications on MongoDB | O11: most | P11: Senior | Q11: 5+ in distributed systems or foundational cloud services | R11: none named | S11: Python, Go and Java (interest) | T11: core components of high-scale distributed or data systems (capability); design, testing, debugging, performance tuning (capability); long-lived highly concurrent codebases (capability); delivering distributed systems or database projects (capability) | U11: Kubernetes (product); AI frameworks and tools (capability); mentoring (capability) | V11: d | W11: none stated | X11: none | Y11: hybrid | Z11: unknown | AA11: n/a | AB11: n/a | AC11: n/a | AD11: n/a | AE11: n/a | AF11: n/a | AG11: app | AH11: AI applications; AI frameworks | AI11: preferred | AJ11: none | AK11: none | AL11: none | AM11: none | AN11: read on the Dreamwork mirror (updated 2 days before retrieval); mirror pay estimate left out; lane d: data-platform software
A12: CL-011 | B12: C030 | C12: India | D12: India | E12: Bengaluru | F12: Databricks | G12: Senior Software Engineer (Infra) | H12: P-926 (job 7619810002) | I12: https://www.databricks.com/company/careers/engineering---pipeline/senior-software-engineer-infra-7619810002 | J12: career page | K12: 2026-10-27 | L12: unknown | M12: open | N12: Build backend connectivity services for networking infrastructure linking the control plane and compute plane | O12: most | P12: Senior | Q12: 6+ production (3+ large distributed systems from scratch) | R12: one of Python, Java, Scala, C++ or similar | S12: none | T12: production code in one of Python, Java, Scala, C++ (capability); large-scale distributed systems built from scratch (capability); SaaS or service-oriented architecture (capability) | U12: networking background (capability) | V12: a | W12: 6+ years production-level code; 3+ years building large distributed systems from scratch | X12: no recent large production codebase of his own; IBM automation work (per plan s2, Om to confirm) | Y12: unknown | Z12: unknown | AA12: n/a | AB12: n/a | AC12: n/a | AD12: n/a | AE12: n/a | AF12: n/a | AG12: none | AH12: none | AI12: none | AJ12: none | AK12: none (multi-cloud context only) | AL12: none | AM12: none | AN12: Python allowed; control-plane to compute-plane connectivity; from-scratch distributed-systems screen is a real gap
... A71: CL-073 | B71: C011 | C71: India | D71: India | E71: Hyderabad | F71: F5 | G71: Senior Software Engineer (intelligence analytics, lead) | H71: RP1039208 | I71: https://ffive.wd5.myworkdayjobs.com/f5jobs/job/Hyderabad-SEZ/Senior-Software-Engineer_RP1039208 | J71: board | K71: 2026-10-27 | L71: 2026-10-26 | M71: open | N71: Architect, build and lead cloud-native intelligence analytics systems (back end, data warehouse, some front end); set coding practices, testing strategy and CI/CD quality gates | O71: most | P71: Senior (lead duties) | Q71: 8+ with a degree, or 10+ | R71: one of Go, Python, Java or similar | S71: React familiarity; PromQL preferred | T71: 8+ years software engineering (capability); 2+ years technical leadership (capability); cloud-native analytics solutions (capability); Go, Python or Java (product); SQL and NoSQL design and tuning (capability); data warehouse analytics (capability); React familiarity (product); ML and AI techniques familiarity (capability); observability (capability); Docker, Kubernetes, microservices on AWS or GCP (product) | U71: PromQL, Tableau, Grafana (product); ML models and AI techniques for decisions (capability) | V71: a | W71: 2+ years in technical leadership or engineering management | X71: IBM team leadership (per plan s2, Om to confirm) | Y71: unknown | Z71: unknown | AA71: n/a | AB71: n/a | AC71: n/a | AD71: n/a | AE71: n/a | AF71: n/a | AG71: none | AH71: machine learning models and AI techniques (familiarity) | AI71: required | AJ71: none | AK71: AWS or GCP required | AL71: none | AM71: none | AN71: read on the Dreamwork mirror (posted yesterday, so 2026-10-26); ai_req required means familiarity with ML and AI techniques, not AI infrastructure; Om s management years may count toward the leadership screen

Sheet LinkedIn
A1: id | B1: company_no | C1: region | D1: country | E1: city | F1: employer | G1: title | H1: req_id | I1: url | J1: source | K1: retrieved | L1: posted | M1: status | N1: work_summary | O1: build_share | P1: level | Q1: years_asked | R1: langs_required | S1: langs_alt_or_optional | T1: skills_required | U1: skills_preferred | V1: lane | W1: prod_history_screen | X1: om_evidence | Y1: work_model | Z1: pay_stated | AA1: english_team | AB1: local_language | AC1: language_years_screen | AD1: interview_format | AE1: where_held | AF1: india_candidates | AG1: ai_infra | AH1: ai_terms | AI1: ai_req | AJ1: helm | AK1: public_cloud | AL1: terraform | AM1: k8s_controllers | AN1: notes
A2: CL-074 | B2: C005 | C2: India | D2: India | E2: Bengaluru | F2: Oracle (OCI) | G2: Senior Platform Software Engineer | H2: 342725 (from the Apply link to Oracle HCM); LinkedIn job 4481449302 | I2: https://www.linkedin.com/jobs/view/4481449302/ | J2: Om LinkedIn | K2: 2026-10-28 | L2: 2026-10-27 | M2: open | N2: Design and build components of OCI s internal artifact management platform (manage, migrate, replicate and serve build artifacts at high volume and strict availability); build migration tooling from legacy systems; integrate with OCI CI/CD and deployment systems | O2: most | P2: Senior (Career Level IC3, individual contributor) | Q2: unknown | R2: none named | S2: none named | T2: building scalable distributed systems (capability); cloud infrastructure (capability); CI/CD systems, artifact repositories, build systems or developer productivity platforms (capability); data migration and data consistency (capability); production rollout strategies (capability); ownership, technical judgment, collaboration and mentoring (capability) | U2: Oracle Cloud Infrastructure experience (product) | V2: a | W2: proven experience building scalable distributed systems; experience with production rollout strategies (no years stated) | X2: IBM registry cost reduction story; IKS upgrade programme (per plan s2, Om to confirm) | Y2: on-site (Bengaluru), full-time, per LinkedIn | Z2: unknown | AA2: n/a | AB2: n/a | AC2: n/a | AD2: n/a | AE2: n/a | AF2: n/a | AG2: none | AH2: none | AI2: none | AJ2: none | AK2: cloud infrastructure required, no provider named; OCI preferred | AL2: none | AM2: none | AN2: Om LinkedIn capture 2 (claude/harvest/linkedin/2026-10-28-raw.md); Oracle s own page for job 342725 loaded no body on 2026-10-28, so the LinkedIn text is the evidence; posted computed from 1 day ago on the 2026-10-28 capture; lane a: backend infrastructure with no language named (as CL-034); the page names no language, tool or product except OCI, so its signal is capabilities only (distributed systems, migration with consistency, rollout, CI/CD integration, disaster recovery); a registry is one kind of artifact repository, so the IBM registry story may map, Om to confirm; same title as an unread Oracle Dreamwork row in Excluded (de04036e), which may be this job or another Oracle team (another post with this title is for Managed Kubernetes); re-check both in W6

Sheet Naukri
A1: id | B1: company_no | C1: region | D1: country | E1: city | F1: employer | G1: title | H1: req_id | I1: url | J1: source | K1: retrieved | L1: posted | M1: status | N1: work_summary | O1: build_share | P1: level | Q1: years_asked | R1: langs_required | S1: langs_alt_or_optional | T1: skills_required | U1: skills_preferred | V1: lane | W1: prod_history_screen | X1: om_evidence | Y1: work_model | Z1: pay_stated | AA1: english_team | AB1: local_language | AC1: language_years_screen | AD1: interview_format | AE1: where_held | AF1: india_candidates | AG1: ai_infra | AH1: ai_terms | AI1: ai_req | AJ1: helm | AK1: public_cloud | AL1: terraform | AM1: k8s_controllers | AN1: notes

Sheet AI probe
A1: id | B1: company_no | C1: region | D1: country | E1: city | F1: employer | G1: title | H1: req_id | I1: url | J1: source | K1: retrieved | L1: posted | M1: status | N1: work_summary | O1: build_share | P1: level | Q1: years_asked | R1: langs_required | S1: langs_alt_or_optional | T1: skills_required | U1: skills_preferred | V1: lane | W1: prod_history_screen | X1: om_evidence | Y1: work_model | Z1: pay_stated | AA1: english_team | AB1: local_language | AC1: language_years_screen | AD1: interview_format | AE1: where_held | AF1: india_candidates | AG1: ai_infra | AH1: ai_terms | AI1: ai_req | AJ1: helm | AK1: public_cloud | AL1: terraform | AM1: k8s_controllers | AN1: notes

Sheet Excluded
A1: id | B1: company_no | C1: employer | D1: title | E1: url | F1: retrieved | G1: reason | H1: reason_group | I1: chatgpt_list
A2: EX-001 | B2: web | C2: StarTree | D2: Senior Software Engineer, Cloud Platform - INDIA | E2: https://job-boards.greenhouse.io/startree/jobs/6177349004 | F2: 2026-10-27 | G2: withdrawn: company is on ChatGPT's list (G008 StarTree); Claude had classified it as lane b, ai_infra none; handed over, not counted by Claude | H2: withdrawn (ChatGPT company) | I2: G008
A3: EX-002 | B3: web | C3: StarTree | D3: Senior Software Engineer, Data Platform (India, Remote) | E3: https://job-boards.greenhouse.io/startree/jobs/6142775004 | F3: 2026-10-27 | G3: withdrawn: company is on ChatGPT's list (G008 StarTree); Claude had classified it as lane d, ai_infra none; handed over, not counted by Claude | H3: withdrawn (ChatGPT company) | I3: G008
A4: EX-003 | B4: web | C4: GitLab | D4: Senior Backend Engineer, India | E4: https://job-boards.greenhouse.io/gitlab/jobs/8716143002 | F4: 2026-10-27 | G4: withdrawn: company is on ChatGPT's list (G025 GitLab); Claude had classified it as lane a, ai_infra app; handed over, not counted by Claude | H4: withdrawn (ChatGPT company) | I4: G025
A5: EX-004 | B5: C001 | C5: Nutanix | D5: Senior Member Of Technical Staff IC5 (Distributed Systems, Python & Golang) 10-14 Yrs | E5: https://careers.blumbergcapital.com/companies/nutanix/jobs/86252806-senior-member-of-technical-staff-ic5-distributed-systems-python-golang-10-14-yrs | F5: 2026-10-27 | G5: closed (posted 2026-07-14; no longer accepting applications) | H5: closed or removed
A6: EX-005 | B6: C001 | C6: Nutanix | D6: Senior Staff Engineer - Nutanix Kubernetes Platform (NKP) | E6: https://jobs.jobvite.com/nutanix/job/ojpGAfwI | F6: 2026-10-27 | G6: years 15-20+ and leads 15-20 engineers; above Om's 12 years | H6: years outside fit
A7: EX-006 | B7: C004 | C7: Red Hat | D7: Senior Software Engineer - Cloud Infrastructure, Kubernetes, Golang/Python | E7: https://jobs.anitab.org/companies/red-hat/jobs/81316096-senior-software-engineer-cloud-infrastructure-kubernetes-golang-python | F7: 2026-10-27 | G7: older than 3 months (posted 2026-06-02); IBM group | H7: older than 3 months
A8: EX-007 | B8: C001 | C8: Nutanix | D8: Member of Technical Staff 4 - NKP | E8: https://jobs.khoslaventures.com/companies/nutanix/jobs/62638628-member-of-technical-staff-4-nkp | F8: 2026-10-27 | G8: older than 3 months (posted 2025-11-25) | H8: older than 3 months
A9: EX-008 | B9: C003 | C9: Cisco | D9: Software Engineering Technical Leader | Golang, AWS, K8s, Microservices | 12-15 Years | E9: https://builtinbengaluru.in/job/software-engineering-technical-leader-golang-aws-k8-s-microservices-12-15-years-bangalore/10572927 | F9: 2026-10-27 | G9: closed (removed 2026-08-20) | H9: closed or removed
A10: EX-009 | B10: C003 | C10: Cisco | D10: Software Engineer - Kubernetes Platform + Go, Python | 8+ years | E10: https://jobs.cisco.com/jobs/ProjectDetail/Software-Engineer-Kubernetes-Platform-Go-Python-8-years-exp/1424177 | F10: 2026-10-27 | G10: closed (job link redirects to the careers home page) | H10: closed or removed
A11: EX-010 | B11: C008 | C11: Dell Technologies | D11: Software Senior Engineer (Python, Golang) | E11: https://jobs.dell.com/es/trabajo/bengaluru/software-senior-engineer-python-golang/375/82688422320 | F11: 2026-10-27 | G11: closed (job link redirects to a 404 page) | H11: closed or removed
A12: EX-011 | B12: C005 | C12: Oracle (OCI) | D12: Senior Member of Technical Staff - Oracle Cloud Infrastructure | E12: https://careers.oracle.com/en/sites/jobsearch/job/303962 | F12: 2026-10-27 | G12: unread (page body does not load for Claude tools) | H12: unread or unverifiable
A13: EX-012 | B13: C002 | C13: Broadcom (VMware) | D13: Kubernetes Platform Tech Manager | E13: https://builtinbengaluru.in/job/kubernetes-platform-tech-manager/7781883 | F13: 2026-10-27 | G13: closed (removed 2026-01-28); also people manager with sales-facing duties | H13: closed or removed
A14: EX-013 | B14: C009 | C14: Hewlett Packard Enterprise | D14: Developer - Kubernetes Platform | E14: https://jobs.accel.com/companies/hpe-simplivity-2-3e24c8e1-09a8-43f1-8671-b32d18dc0fb9/jobs/85816142-developer-kubernetes-platform | F14: 2026-10-27 | G14: closed (posted 2026-07-09); 2-4 years, junior for Om | H14: closed or removed
A15: EX-014 | B15: C011 | C15: F5 | D15: Software Development Engineer III (Volterra) | E15: https://jobs.khoslaventures.com/companies/volterra/jobs/92559837-software-development-engineer-iii | F15: 2026-10-27 | G15: C++ required with Go | H15: other language required
A16: EX-015 | B16: C011 | C16: F5 | D16: Sr Software Development Engineer (Volterra, Hyderabad) | E16: https://jobs.khoslaventures.com/companies/volterra/jobs/81388456-sr-software-development-engineer | F16: 2026-10-27 | G16: older than 3 months (posted 2026-06-03); telecom data path in C/C++/Go | H16: older than 3 months
... A22: EX-021 | B22: C017 | C22: Rubrik | D22: Senior Software Engineer - Cloud Native Protection | E22: https://builtinbengaluru.in/job/senior-software-engineer/7568944 | F22: 2026-10-27 | G22: closed (removed 2025-12-08) | H22: closed or removed
A23: EX-022 | B23: web | C23: New Relic | D23: Senior Software Engineer - GoLang, Kubernetes & Database Platform (R0000072) | E23: https://jobs.accel.com/companies/new-relic/jobs/63578601-senior-software-engineer-golang-kubernetes-database-platform-r0000072-bangalore | F23: 2026-10-27 | G23: closed (6+ months old) | H23: closed or removed | I23: G017
A24: EX-023 | B24: C019 | C24: Druva | D24: Senior Staff Software Engineer (Pune) | E24: https://builtin.com/job/senior-staff-software-engineer/9700062 | F24: 2026-10-27 | G24: closed (removed 2026-08-03) | H24: closed or removed
A25: EX-024 | B25: C015 | C25: Akamai | D25: Senior Software Engineer (Instahyre listing) | E25: https://www.instahyre.com/job-39011-senior-software-engineer-at-akamai-bangalore/ | F25: 2026-10-27 | G25: unread (Instahyre page does not load for Claude tools) | H25: unread or unverifiable
A26: EX-025 | B26: C021 | C26: NVIDIA | D26: Senior System Software Engineer - Infrastructure | E26: https://getmereferred.com/job-listing/senior-system-software-engineer-infrastructure-nvidia-bengaluru-5-to-10-years-experience-63ac2333-bc02-45d0-b145-9db9666541ac | F26: 2026-10-27 | G26: older than 3 months (posted 2025-08-29) | H26: older than 3 months
A27: EX-026 | B27: C021 | C27: NVIDIA | D27: Senior Systems Software Engineer, Containers, Kubernetes, and Confidential Computing | E27: https://jobs.nvidia.com/careers/job/893398004321?domain=nvidia.com&l1=en | F27: 2026-10-27 | G27: unread (page body does not load) | H27: unread or unverifiable
A28: EX-027 | B28: C015 | C28: Akamai | D28: Senior II Software Engineer | E28: https://builtin.com/job/senior-ii-software-engineer/9647335 | F28: 2026-10-27 | G28: closed (removed 2026-06-10); Salesforce development role | H28: closed or removed
A29: EX-028 | B29: C021 | C29: NVIDIA | D29: Senior Distributed Software Engineer, Golang - DGX Cloud | E29: https://zapply.jobs/jobs/0bb4c9f5-8bbf-4e17-847a-3766d6ae68af/ | F29: 2026-10-27 | G29: not India (Santa Clara, US) | H29: not India
A30: EX-029 | B30: C021 | C30: NVIDIA | D30: Senior Software Engineer, Distributed Systems Engineer - DGX Cloud | E30: https://freehire.me/jobs/senior-software-engineer-distributed-systems-engineer-dgx-cloud-nvidia-7hzfkqwb | F30: 2026-10-27 | G30: not India (Santa Clara, US) | H30: not India
A31: EX-030 | B31: C023 | C31: Intel | D31: Cloud Software Development Engineer | E31: https://www.dreamworkhq.com/job/ca575547-16ae-409a-8e44-07e9e0a3c1a1 | F31: 2026-10-27 | G31: unread (page did not load) | H31: unread or unverifiable
A32: EX-031 | B32: C026 | C32: Krutrim | D32: Senior Software Engineer (Weekday listing) | E32: https://jobs.weekday.works/krutrim-senior-software-engineer | F32: 2026-10-27 | G32: unread (page did not load) | H32: unread or unverifiable
A33: EX-032 | B33: C008 | C33: Dell Technologies | D33: Software Senior Engineer-Python, Go, Kubernetes | E33: https://builtin.com/job/software-senior-engineer-python-go-kubernetes/7879090 | F33: 2026-10-27 | G33: closed (removed 2026-01-21) | H33: closed or removed
A34: EX-033 | B34: C029 | C34: Couchbase | D34: Sr Software Engineer (Senior Platform Engineer, Capella Platform) | E34: https://job-boards.greenhouse.io/couchbaseinc/jobs/4609611006 | F34: 2026-10-27 | G34: SRE and cloud operations duties dominate (5+ years platform/SRE, on-call, compliance, Terraform) | H34: SRE, DevOps or ops duties
A35: EX-034 | B35: C035 | C35: ThoughtSpot | D35: Staff Engineer (Cloud Platforms) | E35: https://jobs.sapphireventures.com/companies/thoughtspot/jobs/87981579-staff-engineer-cloud-platforms | F35: 2026-10-27 | G35: closed (posted 2026-07-29) | H35: closed or removed
... A89: EX-088 | B89: web | C89: Netradyne | D89: Senior Staff Engineer - Infrastructure Software | E89: https://www.dreamworkhq.com/job/deef20ca-0931-4516-918c-9b2448f39942 | F89: 2026-10-27 | G89: infra, DevOps and FinOps leadership dominates; building is not most of the role | H89: SRE, DevOps or ops duties
A90: EX-089 | B90: web | C90: New Relic | D90: Senior Software Engineer - Kubernetes Orchestration (R0000335) | E90: https://www.dreamworkhq.com/job/f18247e8-1aa1-4954-90f4-65e26cc93d75 | F90: 2026-10-27 | G90: unread (page did not load) | H90: unread or unverifiable | I90: G017
A91: EX-090 | B91: web | C91: Roku | D91: Senior Software Engineer, Platform Engineering (gh 8095705) | E91: https://www.dreamworkhq.com/job/9ace163f-0b4e-4381-ba4b-638e95a32a78 | F91: 2026-10-27 | G91: repost of CL-009 (same Roku job, gh_jid 8095705) | H91: role identity (not backend infrastructure)
A92: EX-091 | B92: C037 | C92: ServiceNow | D92: Sr Staff Software Engineer (Infrastructure and Operations, Hyderabad) | E92: https://www.dreamworkhq.com/job/31af96c0-33f2-448c-ae3b-8331028d2d7d | F92: 2026-10-27 | G92: years 14+, above Om s 12 (operators, controllers, CRDs, Terraform required) | H92: years outside fit
A93: EX-092 | B93: C024 | C93: DigitalOcean | D93: Senior Software Engineer I - Managed Databases (DBaaS) | E93: https://www.dreamworkhq.com/job/c0f9adb6-ace5-4c62-a453-c6cef7121e02 | F93: 2026-10-27 | G93: unread (page did not load) | H93: unread or unverifiable
A94: EX-093 | B94: C037 | C94: ServiceNow | D94: Sr Software Engineer (Kubernetes Operators & Controllers, Go) | E94: https://www.dreamworkhq.com/job/ac027875-158f-4ffe-931a-5115e4353c4a | F94: 2026-10-27 | G94: unread (page did not load) | H94: unread or unverifiable
A95: EX-094 | B95: C055 | C95: Visa | D95: Sr SW Engineer: Go, Java, Kubernetes, LLM, 3+ yrs | E95: https://www.dreamworkhq.com/job/4c6aabaf-4d83-4d2b-8d36-2a9dccfbff10 | F95: 2026-10-27 | G95: Java and Spring Boot core alongside Go; 3+ years asked, junior for Om | H95: junior
A96: EX-095 | B96: C072 | C96: Razorpay | D96: Lead Software Development Engineer (Staff) | E96: https://www.dreamworkhq.com/job/aecb8c36-24d4-45ef-ba6b-9037459e6368 | F96: 2026-10-27 | G96: closed (no longer in the employer feed; Greenhouse job 4746961005) | H96: closed or removed
A97: EX-096 | B97: C025 | C97: Sarvam AI | D97: Software Engineer - Model API Platform | E97: https://jobs.ashbyhq.com/sarvam/0371342b-5cb8-487b-9310-4d0eb5b37f47 | F97: 2026-10-27 | G97: mid level, 4-6 years, junior for Om; AI terms noted: model API serving, ASR/TTS streaming, LLM serving preferred | H97: junior
A98: EX-097 | B98: C042 | C98: Freshworks | D98: Principal Engineer - Systems (Hyderabad) | E98: https://www.dreamworkhq.com/job/7a5df3d8-7bdb-44df-b780-7752cee7c456 | F98: 2026-10-27 | G98: years 14+, above Om s 12 | H98: years outside fit
...

Sheet Coding
A1: id | B1: employer | C1: company_no | D1: lane | E1: go | F1: python | G1: kubernetes | H1: cloud | I1: aws_named | J1: prod_screen | K1: years_min | L1: band_risk | M1: product_backend | N1: build_share | O1: age_evidence | P1: level_stretch | Q1: source_web
A2: CL-001 | B2: NetApp | C2: C006 | D2: b | E2: required | F2: required | G2: required | H2: required | I2: yes | J2: no | K2: 8 | L2: no | M2: no | N2: most | O2: none | P2: no | Q2: no
A3: CL-002 | B3: NetApp | C3: C006 | D3: d | E3: required | F3: preferred | G3: required | H3: named only | I3: yes | J3: yes | K3: 8 | L3: no | M3: no | N3: most | O3: none | P3: no | Q3: no
A4: CL-003 | B4: Pure Storage (Everpure) | C4: C007 | D4: b | E4: preferred | F4: none | G4: duties only | H4: none | I4: no | J4: yes | K4: 4 | L4: yes | M4: no | N4: most | O4: none | P4: no | Q4: no
A5: CL-004 | B5: Zscaler | C5: C013 | D5: a | E5: allowed | F5: allowed | G5: required | H5: named only | I5: yes | J5: yes | K5: 5 | L5: no | M5: no | N5: half | O5: none | P5: no | Q5: no
A6: CL-005 | B6: Commvault | C6: C020 | D6: a | E6: allowed | F6: allowed | G6: none | H6: none | I6: no | J6: yes | K6: 4 | L6: yes | M6: no | N6: most | O6: none | P6: no | Q6: no
A7: CL-006 | B7: Sarvam AI | C7: C025 | D7: c | E7: allowed | F7: allowed | G7: required | H7: none | I7: no | J7: yes | K7: 5 | L7: no | M7: no | N7: most | O7: none | P7: no | Q7: no
A8: CL-007 | B8: Sarvam AI | C8: C025 | D8: a | E8: allowed | F8: allowed | G8: none | H8: none | I8: no | J8: yes | K8: 5 | L8: no | M8: no | N8: most | O8: none | P8: no | Q8: no
A9: CL-008 | B9: DigitalOcean | C9: C024 | D9: b | E9: required | F9: none | G9: required | H9: none | I9: no | J9: yes | L9: no | M9: no | N9: most | O9: none | P9: no | Q9: no
A10: CL-009 | B10: Roku | C10: web | D10: b | E10: allowed | F10: allowed | G10: required | H10: preferred | I10: yes | J10: yes | K10: 8 | L10: no | M10: no | N10: half | O10: none | P10: no | Q10: yes
A11: CL-010 | B11: MongoDB | C11: C027 | D11: d | E11: preferred | F11: preferred | G11: preferred | H11: none | I11: no | J11: no | K11: 5 | L11: no | M11: no | N11: most | O11: none | P11: no | Q11: no
A12: CL-011 | B12: Databricks | C12: C030 | D12: a | E12: none | F12: allowed | G12: none | H12: none | I12: no | J12: yes | K12: 6 | L12: no | M12: no | N12: most | O12: none | P12: no | Q12: no
A13: CL-012 | B13: ServiceNow | C13: C037 | D13: c | E13: required | F13: none | G13: required | H13: required | I13: yes | J13: yes | K13: 5 | L13: no | M13: no | N13: most | O13: none | P13: no | Q13: no
A14: CL-013 | B14: Intuit | C14: C040 | D14: a | E14: none | F14: allowed | G14: required | H14: required | I14: yes | J14: yes | K14: 8 | L14: no | M14: no | N14: most | O14: none | P14: no | Q14: no
A15: CL-014 | B15: Intuit | C15: C040 | D15: a | E15: none | F15: allowed | G15: required | H15: named only | I15: yes | J15: yes | K15: 10 | L15: no | M15: no | N15: most | O15: none | P15: yes | Q15: no
A16: CL-015 | B16: Nirmata | C16: web | D16: b | E16: allowed | F16: none | G16: required | H16: required | I16: yes | J16: yes | K16: 6 | L16: no | M16: no | N16: most | O16: none | P16: no | Q16: yes
A17: CL-016 | B17: Swiggy | C17: C078 | D17: a | E17: allowed | F17: allowed | G17: none | H17: required | I17: yes | J17: yes | K17: 6 | L17: no | M17: yes | N17: most | O17: relative-weeks | P17: no | Q17: no
A18: CL-017 | B18: Target India | C18: C067 | D18: b | E18: required | F18: none | G18: required | H18: required | I18: yes | J18: yes | K18: 10 | L18: no | M18: no | N18: half | O18: none | P18: no | Q18: no
A19: CL-018 | B19: PayPal | C19: C054 | D19: a | E19: allowed | F19: allowed | G19: required | H19: required | I19: yes | J19: yes | K19: 5 | L19: no | M19: yes | N19: most | O19: date | P19: no | Q19: no
A20: CL-019 | B20: Okta | C20: C049 | D20: b | E20: required | F20: none | G20: required | H20: named only | I20: yes | J20: yes | K20: 6 | L20: no | M20: no | N20: most | O20: none | P20: no | Q20: no
A21: CL-020 | B21: Okta | C21: C049 | D21: b | E21: allowed | F21: allowed | G21: required | H21: required | I21: yes | J21: yes | K21: 5 | L21: no | M21: no | N21: most | O21: relative-weeks | P21: no | Q21: no
... A39: CL-038 | B39: American Express | C39: C057 | D39: b | E39: required | F39: none | G39: required | H39: named only | I39: yes | J39: no | K39: 8 | L39: no | M39: yes | N39: half | O39: date | P39: no | Q39: no
A40: CL-039 | B40: AMD | C40: C022 | D40: a | E40: none | F40: preferred | G40: preferred | H40: preferred | I40: yes | J40: yes | L40: no | M40: no | N40: most | O40: relative-weeks | P40: no | Q40: no
A41: CL-040 | B41: Sarvam AI | C41: C025 | D41: a | E41: allowed | F41: allowed | G41: none | H41: none | I41: no | J41: yes | K41: 8 | L41: no | M41: yes | N41: most | O41: relative-weeks | P41: no | Q41: no
A42: CL-041 | B42: Databricks | C42: C030 | D42: a | E42: none | F42: allowed | G42: none | H42: named only | I42: yes | J42: yes | K42: 12 | L42: no | M42: no | N42: most | O42: updated-only | P42: no | Q42: no
